[08/Mar/2018 03:07:32] INFO [django.server:124] "GET / HTTP/1.1" 200 38538
[08/Mar/2018 03:07:33] WARNING [django.server:124] "GET /api/column/postList/ HTTP/1.1" 401 31
[08/Mar/2018 03:07:33] WARNING [django.server:124] "POST /api/member/userInfo/ HTTP/1.1" 401 31
[08/Mar/2018 03:07:50] INFO [django.server:124] "GET / HTTP/1.1" 200 38919
[08/Mar/2018 03:07:50] INFO [django.server:124] "GET /api/column/postList/ HTTP/1.1" 200 441
[08/Mar/2018 03:08:23] ERROR [django.request:135] Internal Server Error: /api/member/signup/
Traceback (most recent call last):
  File "/Users/joohyonlee/.pyenv/versions/3.6.3/envs/docker-test/lib/python3.6/site-packages/django/core/handlers/exception.py", line 41, in inner
    response = get_response(request)
  File "/Users/joohyonlee/.pyenv/versions/3.6.3/envs/docker-test/lib/python3.6/site-packages/django/core/handlers/base.py", line 187, in _get_response
    response = self.process_exception_by_middleware(e, request)
  File "/Users/joohyonlee/.pyenv/versions/3.6.3/envs/docker-test/lib/python3.6/site-packages/django/core/handlers/base.py", line 185, in _get_response
    response = wrapped_callback(request, *callback_args, **callback_kwargs)
  File "/Users/joohyonlee/.pyenv/versions/3.6.3/envs/docker-test/lib/python3.6/site-packages/django/views/decorators/csrf.py", line 58, in wrapped_view
    return view_func(*args, **kwargs)
  File "/Users/joohyonlee/.pyenv/versions/3.6.3/envs/docker-test/lib/python3.6/site-packages/django/views/generic/base.py", line 68, in view
    return self.dispatch(request, *args, **kwargs)
  File "/Users/joohyonlee/.pyenv/versions/3.6.3/envs/docker-test/lib/python3.6/site-packages/rest_framework/views.py", line 494, in dispatch
    response = self.handle_exception(exc)
  File "/Users/joohyonlee/.pyenv/versions/3.6.3/envs/docker-test/lib/python3.6/site-packages/rest_framework/views.py", line 454, in handle_exception
    self.raise_uncaught_exception(exc)
  File "/Users/joohyonlee/.pyenv/versions/3.6.3/envs/docker-test/lib/python3.6/site-packages/rest_framework/views.py", line 491, in dispatch
    response = handler(request, *args, **kwargs)
  File "/Users/joohyonlee/.pyenv/versions/3.6.3/envs/docker-test/lib/python3.6/site-packages/rest_framework/generics.py", line 192, in post
    return self.create(request, *args, **kwargs)
  File "/Users/joohyonlee/.pyenv/versions/3.6.3/envs/docker-test/lib/python3.6/site-packages/rest_framework/mixins.py", line 21, in create
    self.perform_create(serializer)
  File "/Users/joohyonlee/.pyenv/versions/3.6.3/envs/docker-test/lib/python3.6/site-packages/rest_framework/mixins.py", line 26, in perform_create
    serializer.save()
  File "/Users/joohyonlee/.pyenv/versions/3.6.3/envs/docker-test/lib/python3.6/site-packages/rest_framework/serializers.py", line 214, in save
    self.instance = self.create(validated_data)
  File "/Users/joohyonlee/devocto/octocolumn/octocolumn/member/serializers/user.py", line 60, in create
    email = signup_email_send(user)
  File "/Users/joohyonlee/devocto/octocolumn/octocolumn/utils/customsendmail.py", line 16, in signup_email_send
    url = get_current_site(urlrequest)
  File "/Users/joohyonlee/.pyenv/versions/3.6.3/envs/docker-test/lib/python3.6/site-packages/django/contrib/sites/shortcuts.py", line 15, in get_current_site
    return Site.objects.get_current(request)
  File "/Users/joohyonlee/.pyenv/versions/3.6.3/envs/docker-test/lib/python3.6/site-packages/django/contrib/sites/models.py", line 65, in get_current
    return self._get_site_by_request(request)
  File "/Users/joohyonlee/.pyenv/versions/3.6.3/envs/docker-test/lib/python3.6/site-packages/django/contrib/sites/models.py", line 40, in _get_site_by_request
    host = request.get_host()
AttributeError: module 'django.http.request' has no attribute 'get_host'
[08/Mar/2018 03:08:23] ERROR [django.server:124] "POST /api/member/signup/ HTTP/1.1" 500 27
[08/Mar/2018 03:10:30] WARNING [django.server:124] "POST /api/member/signup/ HTTP/1.1" 400 69
[08/Mar/2018 03:11:20] WARNING [django.server:124] "POST /api/member/signup/ HTTP/1.1" 400 69
[08/Mar/2018 03:11:30] WARNING [django.server:124] "POST /api/member/signup/ HTTP/1.1" 400 69
[08/Mar/2018 03:11:49] WARNING [django.server:124] "POST /api/member/signup/ HTTP/1.1" 400 69
[08/Mar/2018 03:14:12] INFO [django.server:124] "GET / HTTP/1.1" 200 38919
[08/Mar/2018 03:14:12] INFO [django.server:124] "GET /api/column/postList/ HTTP/1.1" 200 441
[08/Mar/2018 03:14:13] INFO [django.server:124] "GET / HTTP/1.1" 200 38919
[08/Mar/2018 03:14:13] INFO [django.server:124] "GET / HTTP/1.1" 200 38919
[08/Mar/2018 03:14:13] INFO [django.server:124] "GET /api/column/postList/ HTTP/1.1" 200 441
[08/Mar/2018 03:14:13] INFO [django.server:124] "GET / HTTP/1.1" 200 38919
[08/Mar/2018 03:14:14] INFO [django.server:124] "GET /api/column/postList/ HTTP/1.1" 200 441
[08/Mar/2018 03:29:00] INFO [django.server:124] "GET /admin/ HTTP/1.1" 302 0
[08/Mar/2018 03:29:00] ERROR [django.request:135] Internal Server Error: /admin/login/
Traceback (most recent call last):
  File "/Users/joohyonlee/.pyenv/versions/3.6.3/envs/docker-test/lib/python3.6/site-packages/django/contrib/sites/models.py", line 44, in _get_site_by_request
    SITE_CACHE[host] = self.get(domain__iexact=host)
  File "/Users/joohyonlee/.pyenv/versions/3.6.3/envs/docker-test/lib/python3.6/site-packages/django/db/models/manager.py", line 85, in manager_method
    return getattr(self.get_queryset(), name)(*args, **kwargs)
  File "/Users/joohyonlee/.pyenv/versions/3.6.3/envs/docker-test/lib/python3.6/site-packages/django/db/models/query.py", line 380, in get
    self.model._meta.object_name
django.contrib.sites.models.DoesNotExist: Site matching query does not exist.

During handling of the above exception, another exception occurred:

Traceback (most recent call last):
  File "/Users/joohyonlee/.pyenv/versions/3.6.3/envs/docker-test/lib/python3.6/site-packages/django/core/handlers/exception.py", line 41, in inner
    response = get_response(request)
  File "/Users/joohyonlee/.pyenv/versions/3.6.3/envs/docker-test/lib/python3.6/site-packages/django/core/handlers/base.py", line 187, in _get_response
    response = self.process_exception_by_middleware(e, request)
  File "/Users/joohyonlee/.pyenv/versions/3.6.3/envs/docker-test/lib/python3.6/site-packages/django/core/handlers/base.py", line 185, in _get_response
    response = wrapped_callback(request, *callback_args, **callback_kwargs)
  File "/Users/joohyonlee/.pyenv/versions/3.6.3/envs/docker-test/lib/python3.6/site-packages/django/views/decorators/cache.py", line 57, in _wrapped_view_func
    response = view_func(request, *args, **kwargs)
  File "/Users/joohyonlee/.pyenv/versions/3.6.3/envs/docker-test/lib/python3.6/site-packages/django/contrib/admin/sites.py", line 393, in login
    return LoginView.as_view(**defaults)(request)
  File "/Users/joohyonlee/.pyenv/versions/3.6.3/envs/docker-test/lib/python3.6/site-packages/django/views/generic/base.py", line 68, in view
    return self.dispatch(request, *args, **kwargs)
  File "/Users/joohyonlee/.pyenv/versions/3.6.3/envs/docker-test/lib/python3.6/site-packages/django/utils/decorators.py", line 67, in _wrapper
    return bound_func(*args, **kwargs)
  File "/Users/joohyonlee/.pyenv/versions/3.6.3/envs/docker-test/lib/python3.6/site-packages/django/views/decorators/debug.py", line 76, in sensitive_post_parameters_wrapper
    return view(request, *args, **kwargs)
  File "/Users/joohyonlee/.pyenv/versions/3.6.3/envs/docker-test/lib/python3.6/site-packages/django/utils/decorators.py", line 63, in bound_func
    return func.__get__(self, type(self))(*args2, **kwargs2)
  File "/Users/joohyonlee/.pyenv/versions/3.6.3/envs/docker-test/lib/python3.6/site-packages/django/utils/decorators.py", line 67, in _wrapper
    return bound_func(*args, **kwargs)
  File "/Users/joohyonlee/.pyenv/versions/3.6.3/envs/docker-test/lib/python3.6/site-packages/django/utils/decorators.py", line 149, in _wrapped_view
    response = view_func(request, *args, **kwargs)
  File "/Users/joohyonlee/.pyenv/versions/3.6.3/envs/docker-test/lib/python3.6/site-packages/django/utils/decorators.py", line 63, in bound_func
    return func.__get__(self, type(self))(*args2, **kwargs2)
  File "/Users/joohyonlee/.pyenv/versions/3.6.3/envs/docker-test/lib/python3.6/site-packages/django/utils/decorators.py", line 67, in _wrapper
    return bound_func(*args, **kwargs)
  File "/Users/joohyonlee/.pyenv/versions/3.6.3/envs/docker-test/lib/python3.6/site-packages/django/views/decorators/cache.py", line 57, in _wrapped_view_func
    response = view_func(request, *args, **kwargs)
  File "/Users/joohyonlee/.pyenv/versions/3.6.3/envs/docker-test/lib/python3.6/site-packages/django/utils/decorators.py", line 63, in bound_func
    return func.__get__(self, type(self))(*args2, **kwargs2)
  File "/Users/joohyonlee/.pyenv/versions/3.6.3/envs/docker-test/lib/python3.6/site-packages/django/contrib/auth/views.py", line 90, in dispatch
    return super(LoginView, self).dispatch(request, *args, **kwargs)
  File "/Users/joohyonlee/.pyenv/versions/3.6.3/envs/docker-test/lib/python3.6/site-packages/django/views/generic/base.py", line 88, in dispatch
    return handler(request, *args, **kwargs)
  File "/Users/joohyonlee/.pyenv/versions/3.6.3/envs/docker-test/lib/python3.6/site-packages/django/views/generic/edit.py", line 174, in get
    return self.render_to_response(self.get_context_data())
  File "/Users/joohyonlee/.pyenv/versions/3.6.3/envs/docker-test/lib/python3.6/site-packages/django/contrib/auth/views.py", line 124, in get_context_data
    current_site = get_current_site(self.request)
  File "/Users/joohyonlee/.pyenv/versions/3.6.3/envs/docker-test/lib/python3.6/site-packages/django/contrib/sites/shortcuts.py", line 15, in get_current_site
    return Site.objects.get_current(request)
  File "/Users/joohyonlee/.pyenv/versions/3.6.3/envs/docker-test/lib/python3.6/site-packages/django/contrib/sites/models.py", line 65, in get_current
    return self._get_site_by_request(request)
  File "/Users/joohyonlee/.pyenv/versions/3.6.3/envs/docker-test/lib/python3.6/site-packages/django/contrib/sites/models.py", line 50, in _get_site_by_request
    SITE_CACHE[domain] = self.get(domain__iexact=domain)
  File "/Users/joohyonlee/.pyenv/versions/3.6.3/envs/docker-test/lib/python3.6/site-packages/django/db/models/manager.py", line 85, in manager_method
    return getattr(self.get_queryset(), name)(*args, **kwargs)
  File "/Users/joohyonlee/.pyenv/versions/3.6.3/envs/docker-test/lib/python3.6/site-packages/django/db/models/query.py", line 380, in get
    self.model._meta.object_name
django.contrib.sites.models.DoesNotExist: Site matching query does not exist.
[08/Mar/2018 03:29:00] ERROR [django.server:124] "GET /admin/login/?next=/admin/ HTTP/1.1" 500 27
[08/Mar/2018 03:30:26] INFO [django.server:124] "GET /admin/login/?next=/admin/ HTTP/1.1" 200 1738
[08/Mar/2018 03:35:40] INFO [django.server:124] "GET / HTTP/1.1" 200 38919
[08/Mar/2018 03:35:41] INFO [django.server:124] "GET /api/column/postList/ HTTP/1.1" 200 441
[08/Mar/2018 03:35:44] INFO [django.server:124] "GET /write/ HTTP/1.1" 200 38919
[08/Mar/2018 03:35:57] WARNING [django.server:124] "POST /api/member/login/ HTTP/1.1" 401 32
[08/Mar/2018 03:36:23] INFO [django.server:124] "POST /api/member/login/ HTTP/1.1" 200 334
[08/Mar/2018 03:36:23] INFO [django.server:124] "GET / HTTP/1.1" 200 38538
[08/Mar/2018 03:36:23] INFO [django.server:124] "GET /api/column/postList/ HTTP/1.1" 200 441
[08/Mar/2018 03:36:23] INFO [django.server:124] "POST /api/member/userInfo/ HTTP/1.1" 200 142
[08/Mar/2018 03:36:34] INFO [django.server:124] "GET /api/column/postList/ HTTP/1.1" 200 441
[08/Mar/2018 03:36:37] INFO [django.server:124] "GET /write/ HTTP/1.1" 200 28149
[08/Mar/2018 03:36:37] INFO [django.server:124] "POST /api/column/isauthor/ HTTP/1.1" 200 15
[08/Mar/2018 03:36:45] INFO [django.server:124] "OPTIONS /api/column/tmpimageupload/ HTTP/1.1" 200 0
[08/Mar/2018 03:36:45] WARNING [django.server:124] "POST /api/column/tmpimageupload/ HTTP/1.1" 401 49
[08/Mar/2018 03:39:53] INFO [django.server:124] "GET /write/ HTTP/1.1" 200 28149
[08/Mar/2018 03:39:53] INFO [django.server:124] "POST /api/column/isauthor/ HTTP/1.1" 200 15
[08/Mar/2018 03:39:59] WARNING [django.server:124] "POST /api/column/tmpimageupload/ HTTP/1.1" 401 49
[08/Mar/2018 03:45:25] INFO [django.server:124] "GET /write/ HTTP/1.1" 200 28149
[08/Mar/2018 03:45:25] INFO [django.server:124] "POST /api/column/isauthor/ HTTP/1.1" 200 15
[08/Mar/2018 03:45:26] INFO [django.server:124] "GET /write/ HTTP/1.1" 200 28149
[08/Mar/2018 03:45:26] INFO [django.server:124] "POST /api/column/isauthor/ HTTP/1.1" 200 15
[08/Mar/2018 03:45:35] WARNING [django.server:124] "POST /api/column/tmpimageupload/ HTTP/1.1" 401 49
[08/Mar/2018 03:48:46] INFO [django.server:124] "GET /write/ HTTP/1.1" 200 28149
[08/Mar/2018 03:48:46] INFO [django.server:124] "POST /api/column/isauthor/ HTTP/1.1" 200 15
[08/Mar/2018 03:48:55] INFO [django.server:124] "OPTIONS /api/column/tmpimageupload/ HTTP/1.1" 200 0
[08/Mar/2018 03:48:55] WARNING [django.server:124] "POST /api/column/tmpimageupload/ HTTP/1.1" 401 49
[08/Mar/2018 03:51:07] INFO [django.server:124] "GET /write/ HTTP/1.1" 200 28149
[08/Mar/2018 03:51:08] INFO [django.server:124] "POST /api/column/isauthor/ HTTP/1.1" 200 15
[08/Mar/2018 03:51:15] WARNING [django.server:124] "POST /api/column/tmpimageupload/ HTTP/1.1" 406 39
[08/Mar/2018 03:51:33] INFO [django.server:124] "GET /write/ HTTP/1.1" 200 28149
[08/Mar/2018 03:51:34] INFO [django.server:124] "POST /api/column/isauthor/ HTTP/1.1" 200 15
[08/Mar/2018 03:51:35] INFO [django.server:124] "GET /write/ HTTP/1.1" 200 28149
[08/Mar/2018 03:51:35] INFO [django.server:124] "POST /api/column/isauthor/ HTTP/1.1" 200 15
[08/Mar/2018 03:51:35] INFO [django.server:124] "GET /write/ HTTP/1.1" 200 28149
[08/Mar/2018 03:51:35] INFO [django.server:124] "POST /api/column/isauthor/ HTTP/1.1" 200 15
[08/Mar/2018 03:51:35] INFO [django.server:124] "GET /write/ HTTP/1.1" 200 28149
[08/Mar/2018 03:51:36] INFO [django.server:124] "POST /api/column/isauthor/ HTTP/1.1" 200 15
[08/Mar/2018 03:51:36] INFO [django.server:124] "GET /write/ HTTP/1.1" 200 28149
[08/Mar/2018 03:51:36] INFO [django.server:124] "GET /write/ HTTP/1.1" 200 28149
[08/Mar/2018 03:51:36] INFO [django.server:124] "POST /api/column/isauthor/ HTTP/1.1" 200 15
[08/Mar/2018 03:51:39] INFO [django.server:124] "GET / HTTP/1.1" 200 38538
[08/Mar/2018 03:51:39] INFO [django.server:124] "GET /api/column/postList/ HTTP/1.1" 200 441
[08/Mar/2018 03:51:39] INFO [django.server:124] "POST /api/member/userInfo/ HTTP/1.1" 200 142
[08/Mar/2018 03:51:42] INFO [django.server:124] "GET / HTTP/1.1" 200 38538
[08/Mar/2018 03:51:42] INFO [django.server:124] "GET /api/column/postList/ HTTP/1.1" 200 441
[08/Mar/2018 03:51:42] INFO [django.server:124] "POST /api/member/userInfo/ HTTP/1.1" 200 142
[08/Mar/2018 03:51:47] INFO [django.server:124] "GET /write/ HTTP/1.1" 200 28149
[08/Mar/2018 03:51:50] INFO [django.server:124] "POST /api/column/isauthor/ HTTP/1.1" 200 15
[08/Mar/2018 03:52:21] INFO [django.server:124] "GET /write/ HTTP/1.1" 200 38919
[08/Mar/2018 03:52:22] INFO [django.server:124] "GET /api/column/postList/ HTTP/1.1" 200 441
[08/Mar/2018 03:52:22] INFO [django.server:124] "GET /write/ HTTP/1.1" 200 38919
[08/Mar/2018 03:52:23] INFO [django.server:124] "GET /api/column/postList/ HTTP/1.1" 200 441
[08/Mar/2018 03:52:23] INFO [django.server:124] "GET /write/ HTTP/1.1" 200 38919
[08/Mar/2018 03:52:23] INFO [django.server:124] "GET /api/column/postList/ HTTP/1.1" 200 441
[08/Mar/2018 03:52:25] INFO [django.server:124] "GET / HTTP/1.1" 200 38919
[08/Mar/2018 03:52:25] INFO [django.server:124] "GET /api/column/postList/ HTTP/1.1" 200 441
[08/Mar/2018 03:52:39] INFO [django.server:124] "POST /api/member/login/ HTTP/1.1" 200 334
[08/Mar/2018 03:52:39] INFO [django.server:124] "GET / HTTP/1.1" 200 38538
[08/Mar/2018 03:52:39] INFO [django.server:124] "GET /api/column/postList/ HTTP/1.1" 200 441
[08/Mar/2018 03:52:39] INFO [django.server:124] "POST /api/member/userInfo/ HTTP/1.1" 200 142
[08/Mar/2018 03:52:42] INFO [django.server:124] "GET /read/3 HTTP/1.1" 200 12502
[08/Mar/2018 03:52:43] INFO [django.server:124] "GET /write/ HTTP/1.1" 200 28149
[08/Mar/2018 03:52:45] INFO [django.server:124] "POST /api/column/isauthor/ HTTP/1.1" 200 15
[08/Mar/2018 03:53:09] WARNING [django.server:124] "POST /api/column/tmpimageupload/ HTTP/1.1" 406 39
[08/Mar/2018 03:55:53] INFO [django.server:124] "GET /write/ HTTP/1.1" 200 28149
[08/Mar/2018 03:55:54] INFO [django.server:124] "POST /api/column/isauthor/ HTTP/1.1" 200 15
[08/Mar/2018 03:56:06] ERROR [django.request:135] Internal Server Error: /api/column/tmpimageupload/
Traceback (most recent call last):
  File "/Users/joohyonlee/.pyenv/versions/3.6.3/envs/docker-test/lib/python3.6/site-packages/django/core/handlers/exception.py", line 41, in inner
    response = get_response(request)
  File "/Users/joohyonlee/.pyenv/versions/3.6.3/envs/docker-test/lib/python3.6/site-packages/django/core/handlers/base.py", line 187, in _get_response
    response = self.process_exception_by_middleware(e, request)
  File "/Users/joohyonlee/.pyenv/versions/3.6.3/envs/docker-test/lib/python3.6/site-packages/django/core/handlers/base.py", line 185, in _get_response
    response = wrapped_callback(request, *callback_args, **callback_kwargs)
  File "/Users/joohyonlee/.pyenv/versions/3.6.3/envs/docker-test/lib/python3.6/site-packages/django/views/decorators/csrf.py", line 58, in wrapped_view
    return view_func(*args, **kwargs)
  File "/Users/joohyonlee/.pyenv/versions/3.6.3/envs/docker-test/lib/python3.6/site-packages/django/views/generic/base.py", line 68, in view
    return self.dispatch(request, *args, **kwargs)
  File "/Users/joohyonlee/.pyenv/versions/3.6.3/envs/docker-test/lib/python3.6/site-packages/rest_framework/views.py", line 494, in dispatch
    response = self.handle_exception(exc)
  File "/Users/joohyonlee/.pyenv/versions/3.6.3/envs/docker-test/lib/python3.6/site-packages/rest_framework/views.py", line 454, in handle_exception
    self.raise_uncaught_exception(exc)
  File "/Users/joohyonlee/.pyenv/versions/3.6.3/envs/docker-test/lib/python3.6/site-packages/rest_framework/views.py", line 491, in dispatch
    response = handler(request, *args, **kwargs)
  File "/Users/joohyonlee/devocto/octocolumn/octocolumn/column/apis/tmp.py", line 136, in post
    serializer = TempFileSerializer(TempFile.objects.create(author=self.request.user, file=file_obj))
  File "/Users/joohyonlee/.pyenv/versions/3.6.3/envs/docker-test/lib/python3.6/site-packages/django/db/models/manager.py", line 85, in manager_method
    return getattr(self.get_queryset(), name)(*args, **kwargs)
  File "/Users/joohyonlee/.pyenv/versions/3.6.3/envs/docker-test/lib/python3.6/site-packages/django/db/models/query.py", line 392, in create
    obj = self.model(**kwargs)
  File "/Users/joohyonlee/.pyenv/versions/3.6.3/envs/docker-test/lib/python3.6/site-packages/django/db/models/base.py", line 555, in __init__
    _setattr(self, field.name, rel_obj)
  File "/Users/joohyonlee/.pyenv/versions/3.6.3/envs/docker-test/lib/python3.6/site-packages/django/db/models/fields/related_descriptors.py", line 216, in __set__
    self.field.remote_field.model._meta.object_name,
ValueError: Cannot assign "<django.contrib.auth.models.AnonymousUser object at 0x104ebde80>": "TempFile.author" must be a "User" instance.
[08/Mar/2018 03:56:06] ERROR [django.server:124] "POST /api/column/tmpimageupload/ HTTP/1.1" 500 27
[08/Mar/2018 03:58:08] INFO [django.server:124] "GET /write/ HTTP/1.1" 200 28149
[08/Mar/2018 03:58:08] INFO [django.server:124] "GET /write/ HTTP/1.1" 200 28149
[08/Mar/2018 03:58:08] INFO [django.server:124] "POST /api/column/isauthor/ HTTP/1.1" 200 15
[08/Mar/2018 03:58:11] INFO [django.server:124] "GET /write/ HTTP/1.1" 200 28149
[08/Mar/2018 03:58:11] INFO [django.server:124] "POST /api/column/isauthor/ HTTP/1.1" 200 15
[08/Mar/2018 03:58:24] ERROR [django.request:135] Internal Server Error: /api/column/tmpimageupload/
Traceback (most recent call last):
  File "/Users/joohyonlee/.pyenv/versions/3.6.3/envs/docker-test/lib/python3.6/site-packages/django/core/handlers/exception.py", line 41, in inner
    response = get_response(request)
  File "/Users/joohyonlee/.pyenv/versions/3.6.3/envs/docker-test/lib/python3.6/site-packages/django/core/handlers/base.py", line 187, in _get_response
    response = self.process_exception_by_middleware(e, request)
  File "/Users/joohyonlee/.pyenv/versions/3.6.3/envs/docker-test/lib/python3.6/site-packages/django/core/handlers/base.py", line 185, in _get_response
    response = wrapped_callback(request, *callback_args, **callback_kwargs)
  File "/Users/joohyonlee/.pyenv/versions/3.6.3/envs/docker-test/lib/python3.6/site-packages/django/views/decorators/csrf.py", line 58, in wrapped_view
    return view_func(*args, **kwargs)
  File "/Users/joohyonlee/.pyenv/versions/3.6.3/envs/docker-test/lib/python3.6/site-packages/django/views/generic/base.py", line 68, in view
    return self.dispatch(request, *args, **kwargs)
  File "/Users/joohyonlee/.pyenv/versions/3.6.3/envs/docker-test/lib/python3.6/site-packages/rest_framework/views.py", line 494, in dispatch
    response = self.handle_exception(exc)
  File "/Users/joohyonlee/.pyenv/versions/3.6.3/envs/docker-test/lib/python3.6/site-packages/rest_framework/views.py", line 454, in handle_exception
    self.raise_uncaught_exception(exc)
  File "/Users/joohyonlee/.pyenv/versions/3.6.3/envs/docker-test/lib/python3.6/site-packages/rest_framework/views.py", line 491, in dispatch
    response = handler(request, *args, **kwargs)
  File "/Users/joohyonlee/devocto/octocolumn/octocolumn/column/apis/tmp.py", line 137, in post
    serializer = TempFileSerializer(TempFile.objects.create(author=user, file=file_obj))
  File "/Users/joohyonlee/.pyenv/versions/3.6.3/envs/docker-test/lib/python3.6/site-packages/django/db/models/manager.py", line 85, in manager_method
    return getattr(self.get_queryset(), name)(*args, **kwargs)
  File "/Users/joohyonlee/.pyenv/versions/3.6.3/envs/docker-test/lib/python3.6/site-packages/django/db/models/query.py", line 392, in create
    obj = self.model(**kwargs)
  File "/Users/joohyonlee/.pyenv/versions/3.6.3/envs/docker-test/lib/python3.6/site-packages/django/db/models/base.py", line 555, in __init__
    _setattr(self, field.name, rel_obj)
  File "/Users/joohyonlee/.pyenv/versions/3.6.3/envs/docker-test/lib/python3.6/site-packages/django/db/models/fields/related_descriptors.py", line 216, in __set__
    self.field.remote_field.model._meta.object_name,
ValueError: Cannot assign "<QuerySet []>": "TempFile.author" must be a "User" instance.
[08/Mar/2018 03:58:24] ERROR [django.server:124] "POST /api/column/tmpimageupload/ HTTP/1.1" 500 27
[08/Mar/2018 03:59:41] INFO [django.server:124] "GET /write/ HTTP/1.1" 200 28149
[08/Mar/2018 03:59:42] INFO [django.server:124] "POST /api/column/isauthor/ HTTP/1.1" 200 15
[08/Mar/2018 03:59:42] INFO [django.server:124] "GET /write/ HTTP/1.1" 200 28149
[08/Mar/2018 03:59:42] INFO [django.server:124] "POST /api/column/isauthor/ HTTP/1.1" 200 15
[08/Mar/2018 03:59:52] INFO [django.server:124] "OPTIONS /api/column/tmpimageupload/ HTTP/1.1" 200 0
[08/Mar/2018 03:59:52] ERROR [django.request:135] Internal Server Error: /api/column/tmpimageupload/
Traceback (most recent call last):
  File "/Users/joohyonlee/.pyenv/versions/3.6.3/envs/docker-test/lib/python3.6/site-packages/django/core/handlers/exception.py", line 41, in inner
    response = get_response(request)
  File "/Users/joohyonlee/.pyenv/versions/3.6.3/envs/docker-test/lib/python3.6/site-packages/django/core/handlers/base.py", line 187, in _get_response
    response = self.process_exception_by_middleware(e, request)
  File "/Users/joohyonlee/.pyenv/versions/3.6.3/envs/docker-test/lib/python3.6/site-packages/django/core/handlers/base.py", line 185, in _get_response
    response = wrapped_callback(request, *callback_args, **callback_kwargs)
  File "/Users/joohyonlee/.pyenv/versions/3.6.3/envs/docker-test/lib/python3.6/site-packages/django/views/decorators/csrf.py", line 58, in wrapped_view
    return view_func(*args, **kwargs)
  File "/Users/joohyonlee/.pyenv/versions/3.6.3/envs/docker-test/lib/python3.6/site-packages/django/views/generic/base.py", line 68, in view
    return self.dispatch(request, *args, **kwargs)
  File "/Users/joohyonlee/.pyenv/versions/3.6.3/envs/docker-test/lib/python3.6/site-packages/rest_framework/views.py", line 494, in dispatch
    response = self.handle_exception(exc)
  File "/Users/joohyonlee/.pyenv/versions/3.6.3/envs/docker-test/lib/python3.6/site-packages/rest_framework/views.py", line 454, in handle_exception
    self.raise_uncaught_exception(exc)
  File "/Users/joohyonlee/.pyenv/versions/3.6.3/envs/docker-test/lib/python3.6/site-packages/rest_framework/views.py", line 491, in dispatch
    response = handler(request, *args, **kwargs)
  File "/Users/joohyonlee/devocto/octocolumn/octocolumn/column/apis/tmp.py", line 138, in post
    serializer = TempFileSerializer(TempFile.objects.create(author=user, file=file_obj))
  File "/Users/joohyonlee/.pyenv/versions/3.6.3/envs/docker-test/lib/python3.6/site-packages/django/db/models/manager.py", line 85, in manager_method
    return getattr(self.get_queryset(), name)(*args, **kwargs)
  File "/Users/joohyonlee/.pyenv/versions/3.6.3/envs/docker-test/lib/python3.6/site-packages/django/db/models/query.py", line 392, in create
    obj = self.model(**kwargs)
  File "/Users/joohyonlee/.pyenv/versions/3.6.3/envs/docker-test/lib/python3.6/site-packages/django/db/models/base.py", line 555, in __init__
    _setattr(self, field.name, rel_obj)
  File "/Users/joohyonlee/.pyenv/versions/3.6.3/envs/docker-test/lib/python3.6/site-packages/django/db/models/fields/related_descriptors.py", line 216, in __set__
    self.field.remote_field.model._meta.object_name,
ValueError: Cannot assign "<QuerySet []>": "TempFile.author" must be a "User" instance.
[08/Mar/2018 03:59:52] ERROR [django.server:124] "POST /api/column/tmpimageupload/ HTTP/1.1" 500 27
[08/Mar/2018 04:00:06] INFO [django.server:124] "GET /write/ HTTP/1.1" 200 28149
[08/Mar/2018 04:00:06] INFO [django.server:124] "POST /api/column/isauthor/ HTTP/1.1" 200 15
[08/Mar/2018 04:00:13] ERROR [django.request:135] Internal Server Error: /api/column/tmpimageupload/
Traceback (most recent call last):
  File "/Users/joohyonlee/.pyenv/versions/3.6.3/envs/docker-test/lib/python3.6/site-packages/django/core/handlers/exception.py", line 41, in inner
    response = get_response(request)
  File "/Users/joohyonlee/.pyenv/versions/3.6.3/envs/docker-test/lib/python3.6/site-packages/django/core/handlers/base.py", line 187, in _get_response
    response = self.process_exception_by_middleware(e, request)
  File "/Users/joohyonlee/.pyenv/versions/3.6.3/envs/docker-test/lib/python3.6/site-packages/django/core/handlers/base.py", line 185, in _get_response
    response = wrapped_callback(request, *callback_args, **callback_kwargs)
  File "/Users/joohyonlee/.pyenv/versions/3.6.3/envs/docker-test/lib/python3.6/site-packages/django/views/decorators/csrf.py", line 58, in wrapped_view
    return view_func(*args, **kwargs)
  File "/Users/joohyonlee/.pyenv/versions/3.6.3/envs/docker-test/lib/python3.6/site-packages/django/views/generic/base.py", line 68, in view
    return self.dispatch(request, *args, **kwargs)
  File "/Users/joohyonlee/.pyenv/versions/3.6.3/envs/docker-test/lib/python3.6/site-packages/rest_framework/views.py", line 494, in dispatch
    response = self.handle_exception(exc)
  File "/Users/joohyonlee/.pyenv/versions/3.6.3/envs/docker-test/lib/python3.6/site-packages/rest_framework/views.py", line 454, in handle_exception
    self.raise_uncaught_exception(exc)
  File "/Users/joohyonlee/.pyenv/versions/3.6.3/envs/docker-test/lib/python3.6/site-packages/rest_framework/views.py", line 491, in dispatch
    response = handler(request, *args, **kwargs)
  File "/Users/joohyonlee/devocto/octocolumn/octocolumn/column/apis/tmp.py", line 138, in post
    serializer = TempFileSerializer(TempFile.objects.create(author=user, file=file_obj))
  File "/Users/joohyonlee/.pyenv/versions/3.6.3/envs/docker-test/lib/python3.6/site-packages/django/db/models/manager.py", line 85, in manager_method
    return getattr(self.get_queryset(), name)(*args, **kwargs)
  File "/Users/joohyonlee/.pyenv/versions/3.6.3/envs/docker-test/lib/python3.6/site-packages/django/db/models/query.py", line 392, in create
    obj = self.model(**kwargs)
  File "/Users/joohyonlee/.pyenv/versions/3.6.3/envs/docker-test/lib/python3.6/site-packages/django/db/models/base.py", line 555, in __init__
    _setattr(self, field.name, rel_obj)
  File "/Users/joohyonlee/.pyenv/versions/3.6.3/envs/docker-test/lib/python3.6/site-packages/django/db/models/fields/related_descriptors.py", line 216, in __set__
    self.field.remote_field.model._meta.object_name,
ValueError: Cannot assign "<QuerySet []>": "TempFile.author" must be a "User" instance.
[08/Mar/2018 04:00:13] ERROR [django.server:124] "POST /api/column/tmpimageupload/ HTTP/1.1" 500 27
[08/Mar/2018 04:01:04] INFO [django.server:124] "GET / HTTP/1.1" 200 38538
[08/Mar/2018 04:01:06] INFO [django.server:124] "GET /api/column/postList/ HTTP/1.1" 200 441
[08/Mar/2018 04:01:06] INFO [django.server:124] "POST /api/member/userInfo/ HTTP/1.1" 200 142
[08/Mar/2018 04:01:26] INFO [django.server:124] "GET /read/3 HTTP/1.1" 200 12502
[08/Mar/2018 04:01:27] INFO [django.server:124] "GET /write/ HTTP/1.1" 200 28149
[08/Mar/2018 04:01:30] INFO [django.server:124] "POST /api/column/isauthor/ HTTP/1.1" 200 15
[08/Mar/2018 04:04:37] INFO [django.server:124] "GET /write/ HTTP/1.1" 200 28149
[08/Mar/2018 04:04:37] INFO [django.server:124] "POST /api/column/isauthor/ HTTP/1.1" 200 15
[08/Mar/2018 04:05:41] INFO [django.server:124] "POST /api/column/temp/ HTTP/1.1" 201 22
[08/Mar/2018 04:05:48] INFO [django.server:124] "POST /api/column/temp/ HTTP/1.1" 200 24
[08/Mar/2018 04:05:56] INFO [django.server:124] "POST /api/column/temp/ HTTP/1.1" 200 24
[08/Mar/2018 04:15:28] INFO [django.server:124] "GET / HTTP/1.1" 200 38538
[08/Mar/2018 04:15:28] INFO [django.server:124] "GET /api/column/postList/ HTTP/1.1" 200 441
[08/Mar/2018 04:15:28] INFO [django.server:124] "POST /api/member/userInfo/ HTTP/1.1" 200 142
[08/Mar/2018 04:15:28] INFO [django.server:124] "GET / HTTP/1.1" 200 38538
[08/Mar/2018 04:15:29] INFO [django.server:124] "GET /api/column/postList/ HTTP/1.1" 200 441
[08/Mar/2018 04:15:29] INFO [django.server:124] "POST /api/member/userInfo/ HTTP/1.1" 200 142
[08/Mar/2018 04:15:33] INFO [django.server:124] "GET /write/ HTTP/1.1" 200 28208
[08/Mar/2018 04:15:35] INFO [django.server:124] "POST /api/column/isauthor/ HTTP/1.1" 200 15
[08/Mar/2018 04:15:44] INFO [django.server:124] "OPTIONS /api/column/tmpimageupload/ HTTP/1.1" 200 0
[08/Mar/2018 04:15:44] ERROR [django.request:135] Internal Server Error: /api/column/tmpimageupload/
Traceback (most recent call last):
  File "/Users/joohyonlee/.pyenv/versions/3.6.3/envs/docker-test/lib/python3.6/site-packages/django/core/handlers/exception.py", line 41, in inner
    response = get_response(request)
  File "/Users/joohyonlee/.pyenv/versions/3.6.3/envs/docker-test/lib/python3.6/site-packages/django/core/handlers/base.py", line 187, in _get_response
    response = self.process_exception_by_middleware(e, request)
  File "/Users/joohyonlee/.pyenv/versions/3.6.3/envs/docker-test/lib/python3.6/site-packages/django/core/handlers/base.py", line 185, in _get_response
    response = wrapped_callback(request, *callback_args, **callback_kwargs)
  File "/Users/joohyonlee/.pyenv/versions/3.6.3/envs/docker-test/lib/python3.6/site-packages/django/views/decorators/csrf.py", line 58, in wrapped_view
    return view_func(*args, **kwargs)
  File "/Users/joohyonlee/.pyenv/versions/3.6.3/envs/docker-test/lib/python3.6/site-packages/django/views/generic/base.py", line 68, in view
    return self.dispatch(request, *args, **kwargs)
  File "/Users/joohyonlee/.pyenv/versions/3.6.3/envs/docker-test/lib/python3.6/site-packages/rest_framework/views.py", line 494, in dispatch
    response = self.handle_exception(exc)
  File "/Users/joohyonlee/.pyenv/versions/3.6.3/envs/docker-test/lib/python3.6/site-packages/rest_framework/views.py", line 454, in handle_exception
    self.raise_uncaught_exception(exc)
  File "/Users/joohyonlee/.pyenv/versions/3.6.3/envs/docker-test/lib/python3.6/site-packages/rest_framework/views.py", line 491, in dispatch
    response = handler(request, *args, **kwargs)
  File "/Users/joohyonlee/devocto/octocolumn/octocolumn/column/apis/tmp.py", line 138, in post
    serializer = TempFileSerializer(TempFile.objects.create(author=user, file=file_obj))
  File "/Users/joohyonlee/.pyenv/versions/3.6.3/envs/docker-test/lib/python3.6/site-packages/django/db/models/manager.py", line 85, in manager_method
    return getattr(self.get_queryset(), name)(*args, **kwargs)
  File "/Users/joohyonlee/.pyenv/versions/3.6.3/envs/docker-test/lib/python3.6/site-packages/django/db/models/query.py", line 392, in create
    obj = self.model(**kwargs)
  File "/Users/joohyonlee/.pyenv/versions/3.6.3/envs/docker-test/lib/python3.6/site-packages/django/db/models/base.py", line 555, in __init__
    _setattr(self, field.name, rel_obj)
  File "/Users/joohyonlee/.pyenv/versions/3.6.3/envs/docker-test/lib/python3.6/site-packages/django/db/models/fields/related_descriptors.py", line 216, in __set__
    self.field.remote_field.model._meta.object_name,
ValueError: Cannot assign "<QuerySet []>": "TempFile.author" must be a "User" instance.
[08/Mar/2018 04:15:44] ERROR [django.server:124] "POST /api/column/tmpimageupload/ HTTP/1.1" 500 27
[08/Mar/2018 04:17:39] ERROR [django.request:135] Internal Server Error: /api/column/tmpimageupload/
Traceback (most recent call last):
  File "/Users/joohyonlee/.pyenv/versions/3.6.3/envs/docker-test/lib/python3.6/site-packages/django/core/handlers/exception.py", line 41, in inner
    response = get_response(request)
  File "/Users/joohyonlee/.pyenv/versions/3.6.3/envs/docker-test/lib/python3.6/site-packages/django/core/handlers/base.py", line 187, in _get_response
    response = self.process_exception_by_middleware(e, request)
  File "/Users/joohyonlee/.pyenv/versions/3.6.3/envs/docker-test/lib/python3.6/site-packages/django/core/handlers/base.py", line 185, in _get_response
    response = wrapped_callback(request, *callback_args, **callback_kwargs)
  File "/Users/joohyonlee/.pyenv/versions/3.6.3/envs/docker-test/lib/python3.6/site-packages/django/views/decorators/csrf.py", line 58, in wrapped_view
    return view_func(*args, **kwargs)
  File "/Users/joohyonlee/.pyenv/versions/3.6.3/envs/docker-test/lib/python3.6/site-packages/django/views/generic/base.py", line 68, in view
    return self.dispatch(request, *args, **kwargs)
  File "/Users/joohyonlee/.pyenv/versions/3.6.3/envs/docker-test/lib/python3.6/site-packages/rest_framework/views.py", line 494, in dispatch
    response = self.handle_exception(exc)
  File "/Users/joohyonlee/.pyenv/versions/3.6.3/envs/docker-test/lib/python3.6/site-packages/rest_framework/views.py", line 454, in handle_exception
    self.raise_uncaught_exception(exc)
  File "/Users/joohyonlee/.pyenv/versions/3.6.3/envs/docker-test/lib/python3.6/site-packages/rest_framework/views.py", line 491, in dispatch
    response = handler(request, *args, **kwargs)
  File "/Users/joohyonlee/devocto/octocolumn/octocolumn/column/apis/tmp.py", line 138, in post
    serializer = TempFileSerializer(TempFile.objects.create(author=user, file=file_obj))
  File "/Users/joohyonlee/.pyenv/versions/3.6.3/envs/docker-test/lib/python3.6/site-packages/django/db/models/manager.py", line 85, in manager_method
    return getattr(self.get_queryset(), name)(*args, **kwargs)
  File "/Users/joohyonlee/.pyenv/versions/3.6.3/envs/docker-test/lib/python3.6/site-packages/django/db/models/query.py", line 392, in create
    obj = self.model(**kwargs)
  File "/Users/joohyonlee/.pyenv/versions/3.6.3/envs/docker-test/lib/python3.6/site-packages/django/db/models/base.py", line 555, in __init__
    _setattr(self, field.name, rel_obj)
  File "/Users/joohyonlee/.pyenv/versions/3.6.3/envs/docker-test/lib/python3.6/site-packages/django/db/models/fields/related_descriptors.py", line 216, in __set__
    self.field.remote_field.model._meta.object_name,
ValueError: Cannot assign "<QuerySet []>": "TempFile.author" must be a "User" instance.
[08/Mar/2018 04:17:39] ERROR [django.server:124] "POST /api/column/tmpimageupload/ HTTP/1.1" 500 27
[08/Mar/2018 04:23:22] INFO [django.server:124] "GET /write/ HTTP/1.1" 200 28208
[08/Mar/2018 04:23:22] INFO [django.server:124] "POST /api/column/isauthor/ HTTP/1.1" 200 15
[08/Mar/2018 04:23:23] INFO [django.server:124] "GET /write/ HTTP/1.1" 200 28208
[08/Mar/2018 04:23:23] INFO [django.server:124] "POST /api/column/isauthor/ HTTP/1.1" 200 15
[08/Mar/2018 04:23:36] ERROR [django.request:135] Internal Server Error: /api/column/tmpimageupload/
Traceback (most recent call last):
  File "/Users/joohyonlee/.pyenv/versions/3.6.3/envs/docker-test/lib/python3.6/site-packages/django/core/handlers/exception.py", line 41, in inner
    response = get_response(request)
  File "/Users/joohyonlee/.pyenv/versions/3.6.3/envs/docker-test/lib/python3.6/site-packages/django/core/handlers/base.py", line 187, in _get_response
    response = self.process_exception_by_middleware(e, request)
  File "/Users/joohyonlee/.pyenv/versions/3.6.3/envs/docker-test/lib/python3.6/site-packages/django/core/handlers/base.py", line 185, in _get_response
    response = wrapped_callback(request, *callback_args, **callback_kwargs)
  File "/Users/joohyonlee/.pyenv/versions/3.6.3/envs/docker-test/lib/python3.6/site-packages/django/views/decorators/csrf.py", line 58, in wrapped_view
    return view_func(*args, **kwargs)
  File "/Users/joohyonlee/.pyenv/versions/3.6.3/envs/docker-test/lib/python3.6/site-packages/django/views/generic/base.py", line 68, in view
    return self.dispatch(request, *args, **kwargs)
  File "/Users/joohyonlee/.pyenv/versions/3.6.3/envs/docker-test/lib/python3.6/site-packages/rest_framework/views.py", line 494, in dispatch
    response = self.handle_exception(exc)
  File "/Users/joohyonlee/.pyenv/versions/3.6.3/envs/docker-test/lib/python3.6/site-packages/rest_framework/views.py", line 454, in handle_exception
    self.raise_uncaught_exception(exc)
  File "/Users/joohyonlee/.pyenv/versions/3.6.3/envs/docker-test/lib/python3.6/site-packages/rest_framework/views.py", line 491, in dispatch
    response = handler(request, *args, **kwargs)
  File "/Users/joohyonlee/devocto/octocolumn/octocolumn/column/apis/tmp.py", line 138, in post
    serializer = TempFileSerializer(TempFile.objects.create(author=user, file=file_obj))
  File "/Users/joohyonlee/.pyenv/versions/3.6.3/envs/docker-test/lib/python3.6/site-packages/django/db/models/manager.py", line 85, in manager_method
    return getattr(self.get_queryset(), name)(*args, **kwargs)
  File "/Users/joohyonlee/.pyenv/versions/3.6.3/envs/docker-test/lib/python3.6/site-packages/django/db/models/query.py", line 392, in create
    obj = self.model(**kwargs)
  File "/Users/joohyonlee/.pyenv/versions/3.6.3/envs/docker-test/lib/python3.6/site-packages/django/db/models/base.py", line 555, in __init__
    _setattr(self, field.name, rel_obj)
  File "/Users/joohyonlee/.pyenv/versions/3.6.3/envs/docker-test/lib/python3.6/site-packages/django/db/models/fields/related_descriptors.py", line 216, in __set__
    self.field.remote_field.model._meta.object_name,
ValueError: Cannot assign "<QuerySet []>": "TempFile.author" must be a "User" instance.
[08/Mar/2018 04:23:36] ERROR [django.server:124] "POST /api/column/tmpimageupload/ HTTP/1.1" 500 27
[08/Mar/2018 04:26:34] INFO [django.server:124] "GET /write/ HTTP/1.1" 200 28208
[08/Mar/2018 04:26:35] INFO [django.server:124] "POST /api/column/isauthor/ HTTP/1.1" 200 15
[08/Mar/2018 04:26:47] INFO [django.server:124] "OPTIONS /api/column/tmpimageupload/ HTTP/1.1" 200 0
[08/Mar/2018 04:26:47] ERROR [django.request:135] Internal Server Error: /api/column/tmpimageupload/
Traceback (most recent call last):
  File "/Users/joohyonlee/.pyenv/versions/3.6.3/envs/docker-test/lib/python3.6/site-packages/django/core/handlers/exception.py", line 41, in inner
    response = get_response(request)
  File "/Users/joohyonlee/.pyenv/versions/3.6.3/envs/docker-test/lib/python3.6/site-packages/django/core/handlers/base.py", line 187, in _get_response
    response = self.process_exception_by_middleware(e, request)
  File "/Users/joohyonlee/.pyenv/versions/3.6.3/envs/docker-test/lib/python3.6/site-packages/django/core/handlers/base.py", line 185, in _get_response
    response = wrapped_callback(request, *callback_args, **callback_kwargs)
  File "/Users/joohyonlee/.pyenv/versions/3.6.3/envs/docker-test/lib/python3.6/site-packages/django/views/decorators/csrf.py", line 58, in wrapped_view
    return view_func(*args, **kwargs)
  File "/Users/joohyonlee/.pyenv/versions/3.6.3/envs/docker-test/lib/python3.6/site-packages/django/views/generic/base.py", line 68, in view
    return self.dispatch(request, *args, **kwargs)
  File "/Users/joohyonlee/.pyenv/versions/3.6.3/envs/docker-test/lib/python3.6/site-packages/rest_framework/views.py", line 494, in dispatch
    response = self.handle_exception(exc)
  File "/Users/joohyonlee/.pyenv/versions/3.6.3/envs/docker-test/lib/python3.6/site-packages/rest_framework/views.py", line 454, in handle_exception
    self.raise_uncaught_exception(exc)
  File "/Users/joohyonlee/.pyenv/versions/3.6.3/envs/docker-test/lib/python3.6/site-packages/rest_framework/views.py", line 491, in dispatch
    response = handler(request, *args, **kwargs)
  File "/Users/joohyonlee/devocto/octocolumn/octocolumn/column/apis/tmp.py", line 127, in post
    print(request.COOKIES['token'])
KeyError: 'token'
[08/Mar/2018 04:26:47] ERROR [django.server:124] "POST /api/column/tmpimageupload/ HTTP/1.1" 500 27
[08/Mar/2018 04:27:26] INFO [django.server:124] "GET /write/ HTTP/1.1" 200 28208
[08/Mar/2018 04:27:26] INFO [django.server:124] "POST /api/column/isauthor/ HTTP/1.1" 200 15
[08/Mar/2018 04:27:50] INFO [django.server:124] "GET /write/ HTTP/1.1" 200 28208
[08/Mar/2018 04:27:51] INFO [django.server:124] "POST /api/column/isauthor/ HTTP/1.1" 200 15
[08/Mar/2018 04:27:51] INFO [django.server:124] "GET /write/ HTTP/1.1" 200 28208
[08/Mar/2018 04:27:51] INFO [django.server:124] "POST /api/column/isauthor/ HTTP/1.1" 200 15
[08/Mar/2018 04:29:56] INFO [django.server:124] "GET /write/ HTTP/1.1" 200 28208
[08/Mar/2018 04:29:56] INFO [django.server:124] "POST /api/column/isauthor/ HTTP/1.1" 200 15
[08/Mar/2018 04:29:57] INFO [django.server:124] "GET /write/ HTTP/1.1" 200 28208
[08/Mar/2018 04:29:57] INFO [django.server:124] "POST /api/column/isauthor/ HTTP/1.1" 200 15
[08/Mar/2018 04:29:58] INFO [django.server:124] "GET /write/ HTTP/1.1" 200 28208
[08/Mar/2018 04:29:58] INFO [django.server:124] "POST /api/column/isauthor/ HTTP/1.1" 200 15
[08/Mar/2018 04:30:16] INFO [django.server:124] "OPTIONS /api/column/tmpimageupload/ HTTP/1.1" 200 0
[08/Mar/2018 04:30:16] ERROR [django.request:135] Internal Server Error: /api/column/tmpimageupload/
Traceback (most recent call last):
  File "/Users/joohyonlee/.pyenv/versions/3.6.3/envs/docker-test/lib/python3.6/site-packages/django/core/handlers/exception.py", line 41, in inner
    response = get_response(request)
  File "/Users/joohyonlee/.pyenv/versions/3.6.3/envs/docker-test/lib/python3.6/site-packages/django/core/handlers/base.py", line 187, in _get_response
    response = self.process_exception_by_middleware(e, request)
  File "/Users/joohyonlee/.pyenv/versions/3.6.3/envs/docker-test/lib/python3.6/site-packages/django/core/handlers/base.py", line 185, in _get_response
    response = wrapped_callback(request, *callback_args, **callback_kwargs)
  File "/Users/joohyonlee/.pyenv/versions/3.6.3/envs/docker-test/lib/python3.6/site-packages/django/views/decorators/csrf.py", line 58, in wrapped_view
    return view_func(*args, **kwargs)
  File "/Users/joohyonlee/.pyenv/versions/3.6.3/envs/docker-test/lib/python3.6/site-packages/django/views/generic/base.py", line 68, in view
    return self.dispatch(request, *args, **kwargs)
  File "/Users/joohyonlee/.pyenv/versions/3.6.3/envs/docker-test/lib/python3.6/site-packages/rest_framework/views.py", line 494, in dispatch
    response = self.handle_exception(exc)
  File "/Users/joohyonlee/.pyenv/versions/3.6.3/envs/docker-test/lib/python3.6/site-packages/rest_framework/views.py", line 454, in handle_exception
    self.raise_uncaught_exception(exc)
  File "/Users/joohyonlee/.pyenv/versions/3.6.3/envs/docker-test/lib/python3.6/site-packages/rest_framework/views.py", line 491, in dispatch
    response = handler(request, *args, **kwargs)
  File "/Users/joohyonlee/devocto/octocolumn/octocolumn/column/apis/tmp.py", line 127, in post
    print(request.COOKIES['token'])
KeyError: 'token'
[08/Mar/2018 04:30:16] ERROR [django.server:124] "POST /api/column/tmpimageupload/ HTTP/1.1" 500 27
[08/Mar/2018 04:32:42] INFO [django.server:124] "GET /write/ HTTP/1.1" 200 28208
[08/Mar/2018 04:32:43] INFO [django.server:124] "POST /api/column/isauthor/ HTTP/1.1" 200 15
[08/Mar/2018 04:32:43] INFO [django.server:124] "GET /write/ HTTP/1.1" 200 28208
[08/Mar/2018 04:32:44] INFO [django.server:124] "POST /api/column/isauthor/ HTTP/1.1" 200 15
[08/Mar/2018 04:32:48] ERROR [django.request:135] Internal Server Error: /api/column/tmpimageupload/
Traceback (most recent call last):
  File "/Users/joohyonlee/.pyenv/versions/3.6.3/envs/docker-test/lib/python3.6/site-packages/django/core/handlers/exception.py", line 41, in inner
    response = get_response(request)
  File "/Users/joohyonlee/.pyenv/versions/3.6.3/envs/docker-test/lib/python3.6/site-packages/django/core/handlers/base.py", line 187, in _get_response
    response = self.process_exception_by_middleware(e, request)
  File "/Users/joohyonlee/.pyenv/versions/3.6.3/envs/docker-test/lib/python3.6/site-packages/django/core/handlers/base.py", line 185, in _get_response
    response = wrapped_callback(request, *callback_args, **callback_kwargs)
  File "/Users/joohyonlee/.pyenv/versions/3.6.3/envs/docker-test/lib/python3.6/site-packages/django/views/decorators/csrf.py", line 58, in wrapped_view
    return view_func(*args, **kwargs)
  File "/Users/joohyonlee/.pyenv/versions/3.6.3/envs/docker-test/lib/python3.6/site-packages/django/views/generic/base.py", line 68, in view
    return self.dispatch(request, *args, **kwargs)
  File "/Users/joohyonlee/.pyenv/versions/3.6.3/envs/docker-test/lib/python3.6/site-packages/rest_framework/views.py", line 494, in dispatch
    response = self.handle_exception(exc)
  File "/Users/joohyonlee/.pyenv/versions/3.6.3/envs/docker-test/lib/python3.6/site-packages/rest_framework/views.py", line 454, in handle_exception
    self.raise_uncaught_exception(exc)
  File "/Users/joohyonlee/.pyenv/versions/3.6.3/envs/docker-test/lib/python3.6/site-packages/rest_framework/views.py", line 491, in dispatch
    response = handler(request, *args, **kwargs)
  File "/Users/joohyonlee/devocto/octocolumn/octocolumn/column/apis/tmp.py", line 127, in post
    print(request.COOKIES['token'])
KeyError: 'token'
[08/Mar/2018 04:32:48] ERROR [django.server:124] "POST /api/column/tmpimageupload/ HTTP/1.1" 500 27
[08/Mar/2018 04:34:25] INFO [django.server:124] "GET /write/ HTTP/1.1" 200 28354
[08/Mar/2018 04:34:26] INFO [django.server:124] "POST /api/column/isauthor/ HTTP/1.1" 200 15
[08/Mar/2018 04:34:26] INFO [django.server:124] "GET /write/ HTTP/1.1" 200 28354
[08/Mar/2018 04:34:26] INFO [django.server:124] "GET /write/ HTTP/1.1" 200 28354
[08/Mar/2018 04:34:27] INFO [django.server:124] "POST /api/column/isauthor/ HTTP/1.1" 200 15
[08/Mar/2018 04:35:34] INFO [django.server:124] "GET /write/ HTTP/1.1" 200 28354
[08/Mar/2018 04:35:34] INFO [django.server:124] "GET /write/ HTTP/1.1" 200 28354
[08/Mar/2018 04:35:34] INFO [django.server:124] "POST /api/column/isauthor/ HTTP/1.1" 200 15
[08/Mar/2018 04:35:36] INFO [django.server:124] "GET /write/ HTTP/1.1" 200 28354
[08/Mar/2018 04:35:36] INFO [django.server:124] "POST /api/column/isauthor/ HTTP/1.1" 200 15
[08/Mar/2018 04:35:36] INFO [django.server:124] "GET /write/ HTTP/1.1" 200 28354
[08/Mar/2018 04:35:36] INFO [django.server:124] "GET /write/ HTTP/1.1" 200 28354
[08/Mar/2018 04:35:37] INFO [django.server:124] "POST /api/column/isauthor/ HTTP/1.1" 200 15
[08/Mar/2018 04:35:49] INFO [django.server:124] "GET /write/ HTTP/1.1" 200 28354
[08/Mar/2018 04:35:49] INFO [django.server:124] "POST /api/column/isauthor/ HTTP/1.1" 200 15
[08/Mar/2018 04:36:37] INFO [django.server:124] "GET /write/ HTTP/1.1" 200 28354
[08/Mar/2018 04:36:37] INFO [django.server:124] "POST /api/column/isauthor/ HTTP/1.1" 200 15
[08/Mar/2018 04:36:38] INFO [django.server:124] "GET /write/ HTTP/1.1" 200 28354
[08/Mar/2018 04:36:38] INFO [django.server:124] "POST /api/column/isauthor/ HTTP/1.1" 200 15
[08/Mar/2018 04:36:39] INFO [django.server:124] "GET /write/ HTTP/1.1" 200 28354
[08/Mar/2018 04:36:39] INFO [django.server:124] "POST /api/column/isauthor/ HTTP/1.1" 200 15
[08/Mar/2018 04:38:30] INFO [django.server:124] "GET /write/ HTTP/1.1" 200 28354
[08/Mar/2018 04:38:30] INFO [django.server:124] "POST /api/column/isauthor/ HTTP/1.1" 200 15
[08/Mar/2018 04:38:31] INFO [django.server:124] "GET /write/ HTTP/1.1" 200 28354
[08/Mar/2018 04:38:32] INFO [django.server:124] "POST /api/column/isauthor/ HTTP/1.1" 200 15
[08/Mar/2018 04:38:45] INFO [django.server:124] "GET / HTTP/1.1" 200 38538
[08/Mar/2018 04:38:46] INFO [django.server:124] "GET /api/column/postList/ HTTP/1.1" 200 441
[08/Mar/2018 04:38:46] INFO [django.server:124] "POST /api/member/userInfo/ HTTP/1.1" 200 142
[08/Mar/2018 04:38:49] INFO [django.server:124] "GET /write/ HTTP/1.1" 200 28354
[08/Mar/2018 04:38:51] INFO [django.server:124] "POST /api/column/isauthor/ HTTP/1.1" 200 15
[08/Mar/2018 04:39:19] INFO [django.server:124] "GET / HTTP/1.1" 200 38538
[08/Mar/2018 04:39:20] INFO [django.server:124] "GET /api/column/postList/ HTTP/1.1" 200 441
[08/Mar/2018 04:39:20] INFO [django.server:124] "POST /api/member/userInfo/ HTTP/1.1" 200 142
[08/Mar/2018 04:39:23] INFO [django.server:124] "GET /write/ HTTP/1.1" 200 28354
[08/Mar/2018 04:39:26] INFO [django.server:124] "POST /api/column/isauthor/ HTTP/1.1" 200 15
[08/Mar/2018 04:39:27] INFO [django.server:124] "GET /write/ HTTP/1.1" 200 28354
[08/Mar/2018 04:39:28] INFO [django.server:124] "POST /api/column/isauthor/ HTTP/1.1" 200 15
[08/Mar/2018 04:39:45] INFO [django.server:124] "GET /write/ HTTP/1.1" 200 28354
[08/Mar/2018 04:39:45] INFO [django.server:124] "POST /api/column/isauthor/ HTTP/1.1" 200 15
[08/Mar/2018 04:39:50] INFO [django.server:124] "GET /write/ HTTP/1.1" 200 28354
[08/Mar/2018 04:39:51] INFO [django.server:124] "POST /api/column/isauthor/ HTTP/1.1" 200 15
[08/Mar/2018 04:39:52] INFO [django.server:124] "GET /write/ HTTP/1.1" 200 28354
[08/Mar/2018 04:39:52] INFO [django.server:124] "POST /api/column/isauthor/ HTTP/1.1" 200 15
[08/Mar/2018 04:39:52] INFO [django.server:124] "GET /write/ HTTP/1.1" 200 28354
[08/Mar/2018 04:39:52] INFO [django.server:124] "POST /api/column/isauthor/ HTTP/1.1" 200 15
[08/Mar/2018 04:40:02] INFO [django.server:124] "GET /write/ HTTP/1.1" 200 28354
[08/Mar/2018 04:40:02] INFO [django.server:124] "POST /api/column/isauthor/ HTTP/1.1" 200 15
[08/Mar/2018 04:42:00] INFO [django.server:124] "GET /write/ HTTP/1.1" 200 28354
[08/Mar/2018 04:42:01] INFO [django.server:124] "POST /api/column/isauthor/ HTTP/1.1" 200 15
[08/Mar/2018 04:42:06] INFO [django.server:124] "GET /write/ HTTP/1.1" 200 28354
[08/Mar/2018 04:42:06] INFO [django.server:124] "POST /api/column/isauthor/ HTTP/1.1" 200 15
[08/Mar/2018 04:42:06] INFO [django.server:124] "GET /write/ HTTP/1.1" 200 28354
[08/Mar/2018 04:42:06] INFO [django.server:124] "POST /api/column/isauthor/ HTTP/1.1" 200 15
[08/Mar/2018 04:42:25] INFO [django.server:124] "GET /write/ HTTP/1.1" 200 28354
[08/Mar/2018 04:42:25] INFO [django.server:124] "POST /api/column/isauthor/ HTTP/1.1" 200 15
[08/Mar/2018 04:42:26] INFO [django.server:124] "GET /write/ HTTP/1.1" 200 28354
[08/Mar/2018 04:42:26] INFO [django.server:124] "POST /api/column/isauthor/ HTTP/1.1" 200 15
[08/Mar/2018 04:42:26] INFO [django.server:124] "GET /write/ HTTP/1.1" 200 28354
[08/Mar/2018 04:42:26] INFO [django.server:124] "GET /write/ HTTP/1.1" 200 28354
[08/Mar/2018 04:42:27] INFO [django.server:124] "POST /api/column/isauthor/ HTTP/1.1" 200 15
[08/Mar/2018 04:42:28] INFO [django.server:124] "GET /write/ HTTP/1.1" 200 28354
[08/Mar/2018 04:42:28] INFO [django.server:124] "POST /api/column/isauthor/ HTTP/1.1" 200 15
[08/Mar/2018 04:42:28] INFO [django.server:124] "GET /write/ HTTP/1.1" 200 28354
[08/Mar/2018 04:42:28] INFO [django.server:124] "POST /api/column/isauthor/ HTTP/1.1" 200 15
[08/Mar/2018 04:42:34] INFO [django.server:124] "GET /write/ HTTP/1.1" 200 28354
[08/Mar/2018 04:42:34] INFO [django.server:124] "POST /api/column/isauthor/ HTTP/1.1" 200 15
[08/Mar/2018 04:42:34] INFO [django.server:124] "GET /write/ HTTP/1.1" 200 28354
[08/Mar/2018 04:42:34] INFO [django.server:124] "POST /api/column/isauthor/ HTTP/1.1" 200 15
[08/Mar/2018 04:42:58] INFO [django.server:124] "GET /write/ HTTP/1.1" 200 28354
[08/Mar/2018 04:42:59] INFO [django.server:124] "POST /api/column/isauthor/ HTTP/1.1" 200 15
[08/Mar/2018 04:42:59] INFO [django.server:124] "GET /write/ HTTP/1.1" 200 28354
[08/Mar/2018 04:42:59] INFO [django.server:124] "POST /api/column/isauthor/ HTTP/1.1" 200 15
[08/Mar/2018 04:42:59] INFO [django.server:124] "GET /write/ HTTP/1.1" 200 28354
[08/Mar/2018 04:42:59] INFO [django.server:124] "GET /write/ HTTP/1.1" 200 28354
[08/Mar/2018 04:43:00] INFO [django.server:124] "POST /api/column/isauthor/ HTTP/1.1" 200 15
[08/Mar/2018 04:43:00] INFO [django.server:124] "GET /write/ HTTP/1.1" 200 28354
[08/Mar/2018 04:43:00] INFO [django.server:124] "POST /api/column/isauthor/ HTTP/1.1" 200 15
[08/Mar/2018 04:43:00] INFO [django.server:124] "GET /write/ HTTP/1.1" 200 28354
[08/Mar/2018 04:43:00] INFO [django.server:124] "GET /write/ HTTP/1.1" 200 28354
[08/Mar/2018 04:43:01] INFO [django.server:124] "GET /write/ HTTP/1.1" 200 28354
[08/Mar/2018 04:43:01] INFO [django.server:124] "GET /write/ HTTP/1.1" 200 28354
[08/Mar/2018 04:43:01] INFO [django.server:124] "POST /api/column/isauthor/ HTTP/1.1" 200 15
[08/Mar/2018 04:43:26] ERROR [django.request:135] Internal Server Error: /
Traceback (most recent call last):
  File "/Users/joohyonlee/.pyenv/versions/3.6.3/envs/docker-test/lib/python3.6/site-packages/django/core/handlers/exception.py", line 41, in inner
    response = get_response(request)
  File "/Users/joohyonlee/.pyenv/versions/3.6.3/envs/docker-test/lib/python3.6/site-packages/django/core/handlers/base.py", line 187, in _get_response
    response = self.process_exception_by_middleware(e, request)
  File "/Users/joohyonlee/.pyenv/versions/3.6.3/envs/docker-test/lib/python3.6/site-packages/django/core/handlers/base.py", line 185, in _get_response
    response = wrapped_callback(request, *callback_args, **callback_kwargs)
  File "/Users/joohyonlee/devocto/octocolumn/octocolumn/config/views/index.py", line 16, in index
    if request.COOKIES['token']:
KeyError: 'token'
[08/Mar/2018 04:43:26] ERROR [django.server:124] "GET / HTTP/1.1" 500 27
[08/Mar/2018 04:43:26] WARNING [django.request:152] Not Found: /favicon.ico
[08/Mar/2018 04:43:26] WARNING [django.server:124] "GET /favicon.ico HTTP/1.1" 404 85
[08/Mar/2018 04:43:30] ERROR [django.request:135] Internal Server Error: /
Traceback (most recent call last):
  File "/Users/joohyonlee/.pyenv/versions/3.6.3/envs/docker-test/lib/python3.6/site-packages/django/core/handlers/exception.py", line 41, in inner
    response = get_response(request)
  File "/Users/joohyonlee/.pyenv/versions/3.6.3/envs/docker-test/lib/python3.6/site-packages/django/core/handlers/base.py", line 187, in _get_response
    response = self.process_exception_by_middleware(e, request)
  File "/Users/joohyonlee/.pyenv/versions/3.6.3/envs/docker-test/lib/python3.6/site-packages/django/core/handlers/base.py", line 185, in _get_response
    response = wrapped_callback(request, *callback_args, **callback_kwargs)
  File "/Users/joohyonlee/devocto/octocolumn/octocolumn/config/views/index.py", line 16, in index
    if request.COOKIES['token']:
KeyError: 'token'
[08/Mar/2018 04:43:30] ERROR [django.server:124] "GET / HTTP/1.1" 500 27
[08/Mar/2018 04:44:00] ERROR [django.request:135] Internal Server Error: /
Traceback (most recent call last):
  File "/Users/joohyonlee/.pyenv/versions/3.6.3/envs/docker-test/lib/python3.6/site-packages/django/core/handlers/exception.py", line 41, in inner
    response = get_response(request)
  File "/Users/joohyonlee/.pyenv/versions/3.6.3/envs/docker-test/lib/python3.6/site-packages/django/core/handlers/base.py", line 187, in _get_response
    response = self.process_exception_by_middleware(e, request)
  File "/Users/joohyonlee/.pyenv/versions/3.6.3/envs/docker-test/lib/python3.6/site-packages/django/core/handlers/base.py", line 185, in _get_response
    response = wrapped_callback(request, *callback_args, **callback_kwargs)
  File "/Users/joohyonlee/devocto/octocolumn/octocolumn/config/views/index.py", line 16, in index
    if request.COOKIES['token']:
KeyError: 'token'
[08/Mar/2018 04:44:00] ERROR [django.server:124] "GET / HTTP/1.1" 500 27
[08/Mar/2018 04:44:01] ERROR [django.request:135] Internal Server Error: /
Traceback (most recent call last):
  File "/Users/joohyonlee/.pyenv/versions/3.6.3/envs/docker-test/lib/python3.6/site-packages/django/core/handlers/exception.py", line 41, in inner
    response = get_response(request)
  File "/Users/joohyonlee/.pyenv/versions/3.6.3/envs/docker-test/lib/python3.6/site-packages/django/core/handlers/base.py", line 187, in _get_response
    response = self.process_exception_by_middleware(e, request)
  File "/Users/joohyonlee/.pyenv/versions/3.6.3/envs/docker-test/lib/python3.6/site-packages/django/core/handlers/base.py", line 185, in _get_response
    response = wrapped_callback(request, *callback_args, **callback_kwargs)
  File "/Users/joohyonlee/devocto/octocolumn/octocolumn/config/views/index.py", line 16, in index
    if request.COOKIES['token']:
KeyError: 'token'
[08/Mar/2018 04:44:01] ERROR [django.server:124] "GET / HTTP/1.1" 500 27
[08/Mar/2018 04:44:01] ERROR [django.request:135] Internal Server Error: /
Traceback (most recent call last):
  File "/Users/joohyonlee/.pyenv/versions/3.6.3/envs/docker-test/lib/python3.6/site-packages/django/core/handlers/exception.py", line 41, in inner
    response = get_response(request)
  File "/Users/joohyonlee/.pyenv/versions/3.6.3/envs/docker-test/lib/python3.6/site-packages/django/core/handlers/base.py", line 187, in _get_response
    response = self.process_exception_by_middleware(e, request)
  File "/Users/joohyonlee/.pyenv/versions/3.6.3/envs/docker-test/lib/python3.6/site-packages/django/core/handlers/base.py", line 185, in _get_response
    response = wrapped_callback(request, *callback_args, **callback_kwargs)
  File "/Users/joohyonlee/devocto/octocolumn/octocolumn/config/views/index.py", line 16, in index
    if request.COOKIES['token']:
KeyError: 'token'
[08/Mar/2018 04:44:01] ERROR [django.server:124] "GET / HTTP/1.1" 500 27
[08/Mar/2018 04:44:02] ERROR [django.request:135] Internal Server Error: /
Traceback (most recent call last):
  File "/Users/joohyonlee/.pyenv/versions/3.6.3/envs/docker-test/lib/python3.6/site-packages/django/core/handlers/exception.py", line 41, in inner
    response = get_response(request)
  File "/Users/joohyonlee/.pyenv/versions/3.6.3/envs/docker-test/lib/python3.6/site-packages/django/core/handlers/base.py", line 187, in _get_response
    response = self.process_exception_by_middleware(e, request)
  File "/Users/joohyonlee/.pyenv/versions/3.6.3/envs/docker-test/lib/python3.6/site-packages/django/core/handlers/base.py", line 185, in _get_response
    response = wrapped_callback(request, *callback_args, **callback_kwargs)
  File "/Users/joohyonlee/devocto/octocolumn/octocolumn/config/views/index.py", line 16, in index
    if request.COOKIES['token']:
KeyError: 'token'
[08/Mar/2018 04:44:02] ERROR [django.server:124] "GET / HTTP/1.1" 500 27
[08/Mar/2018 04:44:02] ERROR [django.request:135] Internal Server Error: /
Traceback (most recent call last):
  File "/Users/joohyonlee/.pyenv/versions/3.6.3/envs/docker-test/lib/python3.6/site-packages/django/core/handlers/exception.py", line 41, in inner
    response = get_response(request)
  File "/Users/joohyonlee/.pyenv/versions/3.6.3/envs/docker-test/lib/python3.6/site-packages/django/core/handlers/base.py", line 187, in _get_response
    response = self.process_exception_by_middleware(e, request)
  File "/Users/joohyonlee/.pyenv/versions/3.6.3/envs/docker-test/lib/python3.6/site-packages/django/core/handlers/base.py", line 185, in _get_response
    response = wrapped_callback(request, *callback_args, **callback_kwargs)
  File "/Users/joohyonlee/devocto/octocolumn/octocolumn/config/views/index.py", line 16, in index
    if request.COOKIES['token']:
KeyError: 'token'
[08/Mar/2018 04:44:02] ERROR [django.server:124] "GET / HTTP/1.1" 500 27
[08/Mar/2018 04:44:02] ERROR [django.request:135] Internal Server Error: /
Traceback (most recent call last):
  File "/Users/joohyonlee/.pyenv/versions/3.6.3/envs/docker-test/lib/python3.6/site-packages/django/core/handlers/exception.py", line 41, in inner
    response = get_response(request)
  File "/Users/joohyonlee/.pyenv/versions/3.6.3/envs/docker-test/lib/python3.6/site-packages/django/core/handlers/base.py", line 187, in _get_response
    response = self.process_exception_by_middleware(e, request)
  File "/Users/joohyonlee/.pyenv/versions/3.6.3/envs/docker-test/lib/python3.6/site-packages/django/core/handlers/base.py", line 185, in _get_response
    response = wrapped_callback(request, *callback_args, **callback_kwargs)
  File "/Users/joohyonlee/devocto/octocolumn/octocolumn/config/views/index.py", line 16, in index
    if request.COOKIES['token']:
KeyError: 'token'
[08/Mar/2018 04:44:02] ERROR [django.server:124] "GET / HTTP/1.1" 500 27
[08/Mar/2018 04:44:02] ERROR [django.request:135] Internal Server Error: /
Traceback (most recent call last):
  File "/Users/joohyonlee/.pyenv/versions/3.6.3/envs/docker-test/lib/python3.6/site-packages/django/core/handlers/exception.py", line 41, in inner
    response = get_response(request)
  File "/Users/joohyonlee/.pyenv/versions/3.6.3/envs/docker-test/lib/python3.6/site-packages/django/core/handlers/base.py", line 187, in _get_response
    response = self.process_exception_by_middleware(e, request)
  File "/Users/joohyonlee/.pyenv/versions/3.6.3/envs/docker-test/lib/python3.6/site-packages/django/core/handlers/base.py", line 185, in _get_response
    response = wrapped_callback(request, *callback_args, **callback_kwargs)
  File "/Users/joohyonlee/devocto/octocolumn/octocolumn/config/views/index.py", line 16, in index
    if request.COOKIES['token']:
KeyError: 'token'
[08/Mar/2018 04:44:02] ERROR [django.server:124] "GET / HTTP/1.1" 500 27
[08/Mar/2018 04:45:29] ERROR [django.request:135] Internal Server Error: /
Traceback (most recent call last):
  File "/Users/joohyonlee/.pyenv/versions/3.6.3/envs/docker-test/lib/python3.6/site-packages/django/core/handlers/exception.py", line 41, in inner
    response = get_response(request)
  File "/Users/joohyonlee/.pyenv/versions/3.6.3/envs/docker-test/lib/python3.6/site-packages/django/core/handlers/base.py", line 187, in _get_response
    response = self.process_exception_by_middleware(e, request)
  File "/Users/joohyonlee/.pyenv/versions/3.6.3/envs/docker-test/lib/python3.6/site-packages/django/core/handlers/base.py", line 185, in _get_response
    response = wrapped_callback(request, *callback_args, **callback_kwargs)
  File "/Users/joohyonlee/devocto/octocolumn/octocolumn/config/views/index.py", line 16, in index
    if request.COOKIES['token']:
KeyError: 'token'
[08/Mar/2018 04:45:29] ERROR [django.server:124] "GET / HTTP/1.1" 500 27
[08/Mar/2018 04:45:31] ERROR [django.request:135] Internal Server Error: /
Traceback (most recent call last):
  File "/Users/joohyonlee/.pyenv/versions/3.6.3/envs/docker-test/lib/python3.6/site-packages/django/core/handlers/exception.py", line 41, in inner
    response = get_response(request)
  File "/Users/joohyonlee/.pyenv/versions/3.6.3/envs/docker-test/lib/python3.6/site-packages/django/core/handlers/base.py", line 187, in _get_response
    response = self.process_exception_by_middleware(e, request)
  File "/Users/joohyonlee/.pyenv/versions/3.6.3/envs/docker-test/lib/python3.6/site-packages/django/core/handlers/base.py", line 185, in _get_response
    response = wrapped_callback(request, *callback_args, **callback_kwargs)
  File "/Users/joohyonlee/devocto/octocolumn/octocolumn/config/views/index.py", line 16, in index
    if request.COOKIES['token']:
KeyError: 'token'
[08/Mar/2018 04:45:31] ERROR [django.server:124] "GET / HTTP/1.1" 500 27
[08/Mar/2018 04:46:31] ERROR [django.request:135] Internal Server Error: /
Traceback (most recent call last):
  File "/Users/joohyonlee/.pyenv/versions/3.6.3/envs/docker-test/lib/python3.6/site-packages/django/core/handlers/exception.py", line 41, in inner
    response = get_response(request)
  File "/Users/joohyonlee/.pyenv/versions/3.6.3/envs/docker-test/lib/python3.6/site-packages/django/core/handlers/base.py", line 187, in _get_response
    response = self.process_exception_by_middleware(e, request)
  File "/Users/joohyonlee/.pyenv/versions/3.6.3/envs/docker-test/lib/python3.6/site-packages/django/core/handlers/base.py", line 185, in _get_response
    response = wrapped_callback(request, *callback_args, **callback_kwargs)
  File "/Users/joohyonlee/devocto/octocolumn/octocolumn/config/views/index.py", line 17, in index
    if request.COOKIES['token']:
KeyError: 'token'
[08/Mar/2018 04:46:31] ERROR [django.server:124] "GET / HTTP/1.1" 500 27
[08/Mar/2018 04:46:58] INFO [django.server:124] "GET / HTTP/1.1" 200 38538
[08/Mar/2018 04:46:59] INFO [django.server:124] "GET /api/column/postList/ HTTP/1.1" 200 441
[08/Mar/2018 04:46:59] INFO [django.server:124] "POST /api/member/userInfo/ HTTP/1.1" 200 142
[08/Mar/2018 04:47:26] INFO [django.server:124] "GET / HTTP/1.1" 200 38919
[08/Mar/2018 04:47:26] INFO [django.server:124] "GET /api/column/postList/ HTTP/1.1" 200 441
[08/Mar/2018 04:47:27] INFO [django.server:124] "GET / HTTP/1.1" 200 38919
[08/Mar/2018 04:47:27] INFO [django.server:124] "GET /api/column/postList/ HTTP/1.1" 200 441
[08/Mar/2018 04:47:27] INFO [django.server:124] "GET / HTTP/1.1" 200 38919
[08/Mar/2018 04:47:27] INFO [django.server:124] "GET /api/column/postList/ HTTP/1.1" 200 441
[08/Mar/2018 04:47:27] INFO [django.server:124] "GET / HTTP/1.1" 200 38919
[08/Mar/2018 04:47:27] INFO [django.server:124] "GET /api/column/postList/ HTTP/1.1" 200 441
[08/Mar/2018 04:47:30] INFO [django.server:124] "GET / HTTP/1.1" 200 38919
[08/Mar/2018 04:47:30] INFO [django.server:124] "GET /api/column/postList/ HTTP/1.1" 200 441
[08/Mar/2018 04:47:30] INFO [django.server:124] "GET / HTTP/1.1" 200 38919
[08/Mar/2018 04:47:30] INFO [django.server:124] "GET /api/column/postList/ HTTP/1.1" 200 441
[08/Mar/2018 04:47:56] INFO [django.server:124] "GET / HTTP/1.1" 200 38919
[08/Mar/2018 04:47:56] INFO [django.server:124] "GET /api/column/postList/ HTTP/1.1" 200 441
[08/Mar/2018 04:47:56] INFO [django.server:124] "GET / HTTP/1.1" 200 38919
[08/Mar/2018 04:47:56] INFO [django.server:124] "GET /api/column/postList/ HTTP/1.1" 200 441
[08/Mar/2018 04:47:56] INFO [django.server:124] "GET / HTTP/1.1" 200 38919
[08/Mar/2018 04:47:57] INFO [django.server:124] "GET /api/column/postList/ HTTP/1.1" 200 441
[08/Mar/2018 04:47:57] INFO [django.server:124] "GET / HTTP/1.1" 200 38919
[08/Mar/2018 04:47:57] INFO [django.server:124] "GET /api/column/postList/ HTTP/1.1" 200 441
[08/Mar/2018 04:47:57] INFO [django.server:124] "GET / HTTP/1.1" 200 38919
[08/Mar/2018 04:47:57] INFO [django.server:124] "GET /api/column/postList/ HTTP/1.1" 200 441
[08/Mar/2018 04:48:01] INFO [django.server:124] "GET /write/ HTTP/1.1" 200 38919
[08/Mar/2018 04:48:03] INFO [django.server:124] "GET /api/column/postList/ HTTP/1.1" 200 441
[08/Mar/2018 04:48:05] INFO [django.server:124] "GET /write/ HTTP/1.1" 200 38919
[08/Mar/2018 04:48:05] INFO [django.server:124] "GET /api/column/postList/ HTTP/1.1" 200 441
[08/Mar/2018 04:51:41] INFO [django.server:124] "GET /write/ HTTP/1.1" 200 38919
[08/Mar/2018 04:51:42] INFO [django.server:124] "GET /api/column/postList/ HTTP/1.1" 200 441
[08/Mar/2018 04:51:42] INFO [django.server:124] "GET /write/ HTTP/1.1" 200 38919
[08/Mar/2018 04:51:42] INFO [django.server:124] "GET /api/column/postList/ HTTP/1.1" 200 441
[08/Mar/2018 04:52:00] INFO [django.server:124] "POST /api/member/login/ HTTP/1.1" 200 334
[08/Mar/2018 04:52:00] INFO [django.server:124] "GET / HTTP/1.1" 200 38538
[08/Mar/2018 04:52:00] INFO [django.server:124] "GET /api/column/postList/ HTTP/1.1" 200 441
[08/Mar/2018 04:52:01] INFO [django.server:124] "POST /api/member/userInfo/ HTTP/1.1" 200 142
[08/Mar/2018 04:52:05] INFO [django.server:124] "GET /write/ HTTP/1.1" 200 28435
[08/Mar/2018 04:52:07] INFO [django.server:124] "POST /api/column/isauthor/ HTTP/1.1" 200 15
[08/Mar/2018 04:52:23] ERROR [django.request:135] Internal Server Error: /api/column/tmpimageupload/
Traceback (most recent call last):
  File "/Users/joohyonlee/.pyenv/versions/3.6.3/envs/docker-test/lib/python3.6/site-packages/django/core/handlers/exception.py", line 41, in inner
    response = get_response(request)
  File "/Users/joohyonlee/.pyenv/versions/3.6.3/envs/docker-test/lib/python3.6/site-packages/django/core/handlers/base.py", line 187, in _get_response
    response = self.process_exception_by_middleware(e, request)
  File "/Users/joohyonlee/.pyenv/versions/3.6.3/envs/docker-test/lib/python3.6/site-packages/django/core/handlers/base.py", line 185, in _get_response
    response = wrapped_callback(request, *callback_args, **callback_kwargs)
  File "/Users/joohyonlee/.pyenv/versions/3.6.3/envs/docker-test/lib/python3.6/site-packages/django/views/decorators/csrf.py", line 58, in wrapped_view
    return view_func(*args, **kwargs)
  File "/Users/joohyonlee/.pyenv/versions/3.6.3/envs/docker-test/lib/python3.6/site-packages/django/views/generic/base.py", line 68, in view
    return self.dispatch(request, *args, **kwargs)
  File "/Users/joohyonlee/.pyenv/versions/3.6.3/envs/docker-test/lib/python3.6/site-packages/rest_framework/views.py", line 494, in dispatch
    response = self.handle_exception(exc)
  File "/Users/joohyonlee/.pyenv/versions/3.6.3/envs/docker-test/lib/python3.6/site-packages/rest_framework/views.py", line 454, in handle_exception
    self.raise_uncaught_exception(exc)
  File "/Users/joohyonlee/.pyenv/versions/3.6.3/envs/docker-test/lib/python3.6/site-packages/rest_framework/views.py", line 491, in dispatch
    response = handler(request, *args, **kwargs)
  File "/Users/joohyonlee/devocto/octocolumn/octocolumn/column/apis/tmp.py", line 138, in post
    serializer = TempFileSerializer(TempFile.objects.create(author=user, file=file_obj))
  File "/Users/joohyonlee/.pyenv/versions/3.6.3/envs/docker-test/lib/python3.6/site-packages/django/db/models/manager.py", line 85, in manager_method
    return getattr(self.get_queryset(), name)(*args, **kwargs)
  File "/Users/joohyonlee/.pyenv/versions/3.6.3/envs/docker-test/lib/python3.6/site-packages/django/db/models/query.py", line 392, in create
    obj = self.model(**kwargs)
  File "/Users/joohyonlee/.pyenv/versions/3.6.3/envs/docker-test/lib/python3.6/site-packages/django/db/models/base.py", line 555, in __init__
    _setattr(self, field.name, rel_obj)
  File "/Users/joohyonlee/.pyenv/versions/3.6.3/envs/docker-test/lib/python3.6/site-packages/django/db/models/fields/related_descriptors.py", line 216, in __set__
    self.field.remote_field.model._meta.object_name,
ValueError: Cannot assign "<QuerySet [<User: develop@octocolumn.com>]>": "TempFile.author" must be a "User" instance.
[08/Mar/2018 04:52:23] ERROR [django.server:124] "POST /api/column/tmpimageupload/ HTTP/1.1" 500 27
[08/Mar/2018 04:53:28] INFO [django.server:124] "GET /write/ HTTP/1.1" 200 28435
[08/Mar/2018 04:53:28] INFO [django.server:124] "POST /api/column/isauthor/ HTTP/1.1" 200 15
[08/Mar/2018 04:53:37] ERROR [django.request:135] Internal Server Error: /api/column/tmpimageupload/
Traceback (most recent call last):
  File "/Users/joohyonlee/.pyenv/versions/3.6.3/envs/docker-test/lib/python3.6/site-packages/django/core/handlers/exception.py", line 41, in inner
    response = get_response(request)
  File "/Users/joohyonlee/.pyenv/versions/3.6.3/envs/docker-test/lib/python3.6/site-packages/django/core/handlers/base.py", line 187, in _get_response
    response = self.process_exception_by_middleware(e, request)
  File "/Users/joohyonlee/.pyenv/versions/3.6.3/envs/docker-test/lib/python3.6/site-packages/django/core/handlers/base.py", line 185, in _get_response
    response = wrapped_callback(request, *callback_args, **callback_kwargs)
  File "/Users/joohyonlee/.pyenv/versions/3.6.3/envs/docker-test/lib/python3.6/site-packages/django/views/decorators/csrf.py", line 58, in wrapped_view
    return view_func(*args, **kwargs)
  File "/Users/joohyonlee/.pyenv/versions/3.6.3/envs/docker-test/lib/python3.6/site-packages/django/views/generic/base.py", line 68, in view
    return self.dispatch(request, *args, **kwargs)
  File "/Users/joohyonlee/.pyenv/versions/3.6.3/envs/docker-test/lib/python3.6/site-packages/rest_framework/views.py", line 494, in dispatch
    response = self.handle_exception(exc)
  File "/Users/joohyonlee/.pyenv/versions/3.6.3/envs/docker-test/lib/python3.6/site-packages/rest_framework/views.py", line 454, in handle_exception
    self.raise_uncaught_exception(exc)
  File "/Users/joohyonlee/.pyenv/versions/3.6.3/envs/docker-test/lib/python3.6/site-packages/rest_framework/views.py", line 491, in dispatch
    response = handler(request, *args, **kwargs)
  File "/Users/joohyonlee/devocto/octocolumn/octocolumn/column/apis/tmp.py", line 138, in post
    serializer = TempFileSerializer(TempFile.objects.create(author=user, file=file_obj))
  File "/Users/joohyonlee/.pyenv/versions/3.6.3/envs/docker-test/lib/python3.6/site-packages/django/db/models/manager.py", line 85, in manager_method
    return getattr(self.get_queryset(), name)(*args, **kwargs)
  File "/Users/joohyonlee/.pyenv/versions/3.6.3/envs/docker-test/lib/python3.6/site-packages/django/db/models/query.py", line 392, in create
    obj = self.model(**kwargs)
  File "/Users/joohyonlee/.pyenv/versions/3.6.3/envs/docker-test/lib/python3.6/site-packages/django/db/models/base.py", line 555, in __init__
    _setattr(self, field.name, rel_obj)
  File "/Users/joohyonlee/.pyenv/versions/3.6.3/envs/docker-test/lib/python3.6/site-packages/django/db/models/fields/related_descriptors.py", line 216, in __set__
    self.field.remote_field.model._meta.object_name,
ValueError: Cannot assign "<QuerySet [<User: develop@octocolumn.com>]>": "TempFile.author" must be a "User" instance.
[08/Mar/2018 04:53:37] ERROR [django.server:124] "POST /api/column/tmpimageupload/ HTTP/1.1" 500 27
[08/Mar/2018 04:54:47] INFO [django.server:124] "GET /write/ HTTP/1.1" 200 28188
[08/Mar/2018 04:54:47] INFO [django.server:124] "POST /api/column/isauthor/ HTTP/1.1" 200 15
[08/Mar/2018 04:54:57] INFO [django.server:124] "POST /api/column/tmpimageupload/ HTTP/1.1" 201 129
[08/Mar/2018 04:55:15] ERROR [django.request:135] Internal Server Error: /
Traceback (most recent call last):
  File "/Users/joohyonlee/.pyenv/versions/3.6.3/envs/docker-test/lib/python3.6/site-packages/django/core/handlers/exception.py", line 41, in inner
    response = get_response(request)
  File "/Users/joohyonlee/.pyenv/versions/3.6.3/envs/docker-test/lib/python3.6/site-packages/django/core/handlers/base.py", line 187, in _get_response
    response = self.process_exception_by_middleware(e, request)
  File "/Users/joohyonlee/.pyenv/versions/3.6.3/envs/docker-test/lib/python3.6/site-packages/django/core/handlers/base.py", line 185, in _get_response
    response = wrapped_callback(request, *callback_args, **callback_kwargs)
  File "/Users/joohyonlee/devocto/octocolumn/octocolumn/config/views/index.py", line 17, in index
    if request.COOKIES['token']:
KeyError: 'token'
[08/Mar/2018 04:55:15] ERROR [django.server:124] "GET / HTTP/1.1" 500 27
[08/Mar/2018 04:55:17] ERROR [django.request:135] Internal Server Error: /
Traceback (most recent call last):
  File "/Users/joohyonlee/.pyenv/versions/3.6.3/envs/docker-test/lib/python3.6/site-packages/django/core/handlers/exception.py", line 41, in inner
    response = get_response(request)
  File "/Users/joohyonlee/.pyenv/versions/3.6.3/envs/docker-test/lib/python3.6/site-packages/django/core/handlers/base.py", line 187, in _get_response
    response = self.process_exception_by_middleware(e, request)
  File "/Users/joohyonlee/.pyenv/versions/3.6.3/envs/docker-test/lib/python3.6/site-packages/django/core/handlers/base.py", line 185, in _get_response
    response = wrapped_callback(request, *callback_args, **callback_kwargs)
  File "/Users/joohyonlee/devocto/octocolumn/octocolumn/config/views/index.py", line 17, in index
    if request.COOKIES['token']:
KeyError: 'token'
[08/Mar/2018 04:55:17] ERROR [django.server:124] "GET / HTTP/1.1" 500 27
[08/Mar/2018 04:58:01] INFO [django.server:124] "GET / HTTP/1.1" 200 38919
[08/Mar/2018 04:58:02] INFO [django.server:124] "GET /api/column/postList/ HTTP/1.1" 200 441
[08/Mar/2018 04:58:47] INFO [django.server:124] "POST /api/member/login/ HTTP/1.1" 200 334
[08/Mar/2018 04:58:51] INFO [django.server:124] "GET / HTTP/1.1" 200 38919
[08/Mar/2018 04:58:51] INFO [django.server:124] "GET /api/column/postList/ HTTP/1.1" 200 441
[08/Mar/2018 04:59:04] INFO [django.server:124] "GET / HTTP/1.1" 200 38919
[08/Mar/2018 04:59:04] INFO [django.server:124] "GET /api/column/postList/ HTTP/1.1" 200 441
[08/Mar/2018 04:59:07] INFO [django.server:124] "GET / HTTP/1.1" 200 38919
[08/Mar/2018 04:59:07] INFO [django.server:124] "GET /api/column/postList/ HTTP/1.1" 200 441
[08/Mar/2018 04:59:07] INFO [django.server:124] "GET /api/column/postList/ HTTP/1.1" 200 441
[08/Mar/2018 05:00:00] INFO [django.server:124] "GET / HTTP/1.1" 200 38538
[08/Mar/2018 05:00:00] INFO [django.server:124] "GET /api/column/postList/ HTTP/1.1" 200 441
[08/Mar/2018 05:00:00] INFO [django.server:124] "POST /api/member/userInfo/ HTTP/1.1" 200 142
[08/Mar/2018 05:00:01] INFO [django.server:124] "GET / HTTP/1.1" 200 38538
[08/Mar/2018 05:00:01] INFO [django.server:124] "GET /api/column/postList/ HTTP/1.1" 200 441
[08/Mar/2018 05:00:01] INFO [django.server:124] "POST /api/member/userInfo/ HTTP/1.1" 200 142
[08/Mar/2018 05:00:01] INFO [django.server:124] "GET / HTTP/1.1" 200 38538
[08/Mar/2018 05:00:01] INFO [django.server:124] "GET /api/column/postList/ HTTP/1.1" 200 441
[08/Mar/2018 05:00:01] INFO [django.server:124] "GET /api/column/postList/ HTTP/1.1" 200 441
[08/Mar/2018 05:00:02] INFO [django.server:124] "POST /api/member/userInfo/ HTTP/1.1" 200 142
[08/Mar/2018 05:00:02] INFO [django.server:124] "GET / HTTP/1.1" 200 38538
[08/Mar/2018 05:00:02] INFO [django.server:124] "GET /api/column/postList/ HTTP/1.1" 200 441
[08/Mar/2018 05:00:02] INFO [django.server:124] "GET /api/column/postList/ HTTP/1.1" 200 441
[08/Mar/2018 05:00:02] INFO [django.server:124] "POST /api/member/userInfo/ HTTP/1.1" 200 142
[08/Mar/2018 05:01:19] INFO [django.server:124] "GET / HTTP/1.1" 200 38919
[08/Mar/2018 05:01:19] INFO [django.server:124] "GET /api/column/postList/ HTTP/1.1" 200 441
[08/Mar/2018 05:01:19] INFO [django.server:124] "GET /api/column/postList/ HTTP/1.1" 200 441
[08/Mar/2018 05:01:25] INFO [django.server:124] "GET / HTTP/1.1" 200 38919
[08/Mar/2018 05:01:25] INFO [django.server:124] "GET /api/column/postList/ HTTP/1.1" 200 441
[08/Mar/2018 05:01:36] INFO [django.server:124] "GET / HTTP/1.1" 200 38919
[08/Mar/2018 05:01:36] INFO [django.server:124] "GET /api/column/postList/ HTTP/1.1" 200 441
[08/Mar/2018 05:01:36] INFO [django.server:124] "GET / HTTP/1.1" 200 38919
[08/Mar/2018 05:01:36] INFO [django.server:124] "GET /api/column/postList/ HTTP/1.1" 200 441
[08/Mar/2018 05:01:36] INFO [django.server:124] "GET /api/column/postList/ HTTP/1.1" 200 441
[08/Mar/2018 05:01:36] INFO [django.server:124] "GET / HTTP/1.1" 200 38919
[08/Mar/2018 05:01:37] INFO [django.server:124] "GET /api/column/postList/ HTTP/1.1" 200 441
[08/Mar/2018 05:01:37] INFO [django.server:124] "GET /api/column/postList/ HTTP/1.1" 200 441
[08/Mar/2018 05:01:37] INFO [django.server:124] "GET / HTTP/1.1" 200 38919
[08/Mar/2018 05:01:37] INFO [django.server:124] "GET /api/column/postList/ HTTP/1.1" 200 441
[08/Mar/2018 05:01:37] INFO [django.server:124] "GET /api/column/postList/ HTTP/1.1" 200 441
[08/Mar/2018 05:01:37] INFO [django.server:124] "GET / HTTP/1.1" 200 38919
[08/Mar/2018 05:01:37] INFO [django.server:124] "GET /api/column/postList/ HTTP/1.1" 200 441
[08/Mar/2018 05:01:37] INFO [django.server:124] "GET /api/column/postList/ HTTP/1.1" 200 441
[08/Mar/2018 05:01:37] INFO [django.server:124] "GET / HTTP/1.1" 200 38919
[08/Mar/2018 05:01:38] INFO [django.server:124] "GET /api/column/postList/ HTTP/1.1" 200 441
[08/Mar/2018 05:01:38] INFO [django.server:124] "GET /api/column/postList/ HTTP/1.1" 200 441
[08/Mar/2018 05:01:58] INFO [django.server:124] "GET / HTTP/1.1" 200 38919
[08/Mar/2018 05:01:58] INFO [django.server:124] "GET /api/column/postList/ HTTP/1.1" 200 441
[08/Mar/2018 05:02:04] INFO [django.server:124] "POST /api/member/login/ HTTP/1.1" 200 334
[08/Mar/2018 05:02:04] INFO [django.server:124] "GET / HTTP/1.1" 200 38919
[08/Mar/2018 05:02:04] INFO [django.server:124] "GET /api/column/postList/ HTTP/1.1" 200 441
[08/Mar/2018 05:02:09] INFO [django.server:124] "GET / HTTP/1.1" 200 38919
[08/Mar/2018 05:02:09] INFO [django.server:124] "GET /api/column/postList/ HTTP/1.1" 200 441
[08/Mar/2018 05:02:51] INFO [django.server:124] "GET / HTTP/1.1" 200 38919
[08/Mar/2018 05:02:51] INFO [django.server:124] "GET /api/column/postList/ HTTP/1.1" 200 441
[08/Mar/2018 05:02:51] INFO [django.server:124] "GET /api/column/postList/ HTTP/1.1" 200 441
[08/Mar/2018 05:02:54] INFO [django.server:124] "GET / HTTP/1.1" 200 38538
[08/Mar/2018 05:02:54] INFO [django.server:124] "GET /api/column/postList/ HTTP/1.1" 200 441
[08/Mar/2018 05:02:54] INFO [django.server:124] "POST /api/member/userInfo/ HTTP/1.1" 200 142
[08/Mar/2018 05:02:54] INFO [django.server:124] "GET / HTTP/1.1" 200 38538
[08/Mar/2018 05:02:54] INFO [django.server:124] "POST /api/member/userInfo/ HTTP/1.1" 200 142
[08/Mar/2018 05:02:54] INFO [django.server:124] "GET /api/column/postList/ HTTP/1.1" 200 441
[08/Mar/2018 05:02:55] INFO [django.server:124] "GET / HTTP/1.1" 200 38538
[08/Mar/2018 05:02:55] INFO [django.server:124] "GET /api/column/postList/ HTTP/1.1" 200 441
[08/Mar/2018 05:02:55] INFO [django.server:124] "GET /api/column/postList/ HTTP/1.1" 200 441
[08/Mar/2018 05:02:55] INFO [django.server:124] "POST /api/member/userInfo/ HTTP/1.1" 200 142
[08/Mar/2018 05:03:59] INFO [django.server:124] "GET / HTTP/1.1" 200 38538
[08/Mar/2018 05:03:59] INFO [django.server:124] "GET /api/column/postList/ HTTP/1.1" 200 441
[08/Mar/2018 05:03:59] INFO [django.server:124] "GET /api/column/postList/ HTTP/1.1" 200 441
[08/Mar/2018 05:04:00] INFO [django.server:124] "POST /api/member/userInfo/ HTTP/1.1" 200 142
[08/Mar/2018 05:04:00] INFO [django.server:124] "GET / HTTP/1.1" 200 38538
[08/Mar/2018 05:04:00] INFO [django.server:124] "GET /api/column/postList/ HTTP/1.1" 200 441
[08/Mar/2018 05:04:00] INFO [django.server:124] "GET /api/column/postList/ HTTP/1.1" 200 441
[08/Mar/2018 05:04:00] INFO [django.server:124] "POST /api/member/userInfo/ HTTP/1.1" 200 142
[08/Mar/2018 05:04:00] INFO [django.server:124] "GET / HTTP/1.1" 200 38538
[08/Mar/2018 05:04:01] INFO [django.server:124] "GET /api/column/postList/ HTTP/1.1" 200 441
[08/Mar/2018 05:04:01] INFO [django.server:124] "GET /api/column/postList/ HTTP/1.1" 200 441
[08/Mar/2018 05:04:01] INFO [django.server:124] "POST /api/member/userInfo/ HTTP/1.1" 200 142
[08/Mar/2018 05:04:01] INFO [django.server:124] "GET / HTTP/1.1" 200 38538
[08/Mar/2018 05:04:01] INFO [django.server:124] "GET /api/column/postList/ HTTP/1.1" 200 441
[08/Mar/2018 05:04:01] INFO [django.server:124] "GET /api/column/postList/ HTTP/1.1" 200 441
[08/Mar/2018 05:04:01] INFO [django.server:124] "POST /api/member/userInfo/ HTTP/1.1" 200 142
[08/Mar/2018 05:04:01] INFO [django.server:124] "GET / HTTP/1.1" 200 38538
[08/Mar/2018 05:04:01] INFO [django.server:124] "GET /api/column/postList/ HTTP/1.1" 200 441
[08/Mar/2018 05:04:01] INFO [django.server:124] "GET /api/column/postList/ HTTP/1.1" 200 441
[08/Mar/2018 05:04:01] INFO [django.server:124] "POST /api/member/userInfo/ HTTP/1.1" 200 142
[08/Mar/2018 05:04:10] ERROR [django.request:135] Internal Server Error: /
Traceback (most recent call last):
  File "/Users/joohyonlee/.pyenv/versions/3.6.3/envs/docker-test/lib/python3.6/site-packages/django/core/handlers/exception.py", line 41, in inner
    response = get_response(request)
  File "/Users/joohyonlee/.pyenv/versions/3.6.3/envs/docker-test/lib/python3.6/site-packages/django/core/handlers/base.py", line 187, in _get_response
    response = self.process_exception_by_middleware(e, request)
  File "/Users/joohyonlee/.pyenv/versions/3.6.3/envs/docker-test/lib/python3.6/site-packages/django/core/handlers/base.py", line 185, in _get_response
    response = wrapped_callback(request, *callback_args, **callback_kwargs)
  File "/Users/joohyonlee/devocto/octocolumn/octocolumn/config/views/index.py", line 16, in index
    if request.COOKIES['token']:
KeyError: 'token'
[08/Mar/2018 05:04:10] ERROR [django.server:124] "GET / HTTP/1.1" 500 27
[08/Mar/2018 05:04:10] WARNING [django.request:152] Not Found: /favicon.ico
[08/Mar/2018 05:04:10] WARNING [django.server:124] "GET /favicon.ico HTTP/1.1" 404 85
[08/Mar/2018 05:04:10] ERROR [django.request:135] Internal Server Error: /
Traceback (most recent call last):
  File "/Users/joohyonlee/.pyenv/versions/3.6.3/envs/docker-test/lib/python3.6/site-packages/django/core/handlers/exception.py", line 41, in inner
    response = get_response(request)
  File "/Users/joohyonlee/.pyenv/versions/3.6.3/envs/docker-test/lib/python3.6/site-packages/django/core/handlers/base.py", line 187, in _get_response
    response = self.process_exception_by_middleware(e, request)
  File "/Users/joohyonlee/.pyenv/versions/3.6.3/envs/docker-test/lib/python3.6/site-packages/django/core/handlers/base.py", line 185, in _get_response
    response = wrapped_callback(request, *callback_args, **callback_kwargs)
  File "/Users/joohyonlee/devocto/octocolumn/octocolumn/config/views/index.py", line 16, in index
    if request.COOKIES['token']:
KeyError: 'token'
[08/Mar/2018 05:04:10] ERROR [django.server:124] "GET / HTTP/1.1" 500 27
[08/Mar/2018 05:04:11] ERROR [django.request:135] Internal Server Error: /
Traceback (most recent call last):
  File "/Users/joohyonlee/.pyenv/versions/3.6.3/envs/docker-test/lib/python3.6/site-packages/django/core/handlers/exception.py", line 41, in inner
    response = get_response(request)
  File "/Users/joohyonlee/.pyenv/versions/3.6.3/envs/docker-test/lib/python3.6/site-packages/django/core/handlers/base.py", line 187, in _get_response
    response = self.process_exception_by_middleware(e, request)
  File "/Users/joohyonlee/.pyenv/versions/3.6.3/envs/docker-test/lib/python3.6/site-packages/django/core/handlers/base.py", line 185, in _get_response
    response = wrapped_callback(request, *callback_args, **callback_kwargs)
  File "/Users/joohyonlee/devocto/octocolumn/octocolumn/config/views/index.py", line 16, in index
    if request.COOKIES['token']:
KeyError: 'token'
[08/Mar/2018 05:04:11] ERROR [django.server:124] "GET / HTTP/1.1" 500 27
[08/Mar/2018 05:04:11] ERROR [django.request:135] Internal Server Error: /
Traceback (most recent call last):
  File "/Users/joohyonlee/.pyenv/versions/3.6.3/envs/docker-test/lib/python3.6/site-packages/django/core/handlers/exception.py", line 41, in inner
    response = get_response(request)
  File "/Users/joohyonlee/.pyenv/versions/3.6.3/envs/docker-test/lib/python3.6/site-packages/django/core/handlers/base.py", line 187, in _get_response
    response = self.process_exception_by_middleware(e, request)
  File "/Users/joohyonlee/.pyenv/versions/3.6.3/envs/docker-test/lib/python3.6/site-packages/django/core/handlers/base.py", line 185, in _get_response
    response = wrapped_callback(request, *callback_args, **callback_kwargs)
  File "/Users/joohyonlee/devocto/octocolumn/octocolumn/config/views/index.py", line 16, in index
    if request.COOKIES['token']:
KeyError: 'token'
[08/Mar/2018 05:04:11] ERROR [django.server:124] "GET / HTTP/1.1" 500 27
[08/Mar/2018 05:04:11] ERROR [django.request:135] Internal Server Error: /
Traceback (most recent call last):
  File "/Users/joohyonlee/.pyenv/versions/3.6.3/envs/docker-test/lib/python3.6/site-packages/django/core/handlers/exception.py", line 41, in inner
    response = get_response(request)
  File "/Users/joohyonlee/.pyenv/versions/3.6.3/envs/docker-test/lib/python3.6/site-packages/django/core/handlers/base.py", line 187, in _get_response
    response = self.process_exception_by_middleware(e, request)
  File "/Users/joohyonlee/.pyenv/versions/3.6.3/envs/docker-test/lib/python3.6/site-packages/django/core/handlers/base.py", line 185, in _get_response
    response = wrapped_callback(request, *callback_args, **callback_kwargs)
  File "/Users/joohyonlee/devocto/octocolumn/octocolumn/config/views/index.py", line 16, in index
    if request.COOKIES['token']:
KeyError: 'token'
[08/Mar/2018 05:04:11] ERROR [django.server:124] "GET / HTTP/1.1" 500 27
[08/Mar/2018 05:04:48] INFO [django.server:124] "GET /write/ HTTP/1.1" 200 28188
[08/Mar/2018 05:04:49] INFO [django.server:124] "POST /api/column/isauthor/ HTTP/1.1" 200 15
[08/Mar/2018 05:04:51] INFO [django.server:124] "GET / HTTP/1.1" 200 38538
[08/Mar/2018 05:04:51] INFO [django.server:124] "GET /api/column/postList/ HTTP/1.1" 200 441
[08/Mar/2018 05:04:51] INFO [django.server:124] "POST /api/member/userInfo/ HTTP/1.1" 200 142
[08/Mar/2018 05:04:52] INFO [django.server:124] "GET / HTTP/1.1" 200 38538
[08/Mar/2018 05:04:52] INFO [django.server:124] "GET /api/column/postList/ HTTP/1.1" 200 441
[08/Mar/2018 05:04:52] INFO [django.server:124] "POST /api/member/userInfo/ HTTP/1.1" 200 142
[08/Mar/2018 05:04:52] INFO [django.server:124] "GET / HTTP/1.1" 200 38538
[08/Mar/2018 05:04:53] INFO [django.server:124] "GET /api/column/postList/ HTTP/1.1" 200 441
[08/Mar/2018 05:04:53] INFO [django.server:124] "POST /api/member/userInfo/ HTTP/1.1" 200 142
[08/Mar/2018 05:05:11] INFO [django.server:124] "GET / HTTP/1.1" 200 38919
[08/Mar/2018 05:05:12] INFO [django.server:124] "GET /api/column/postList/ HTTP/1.1" 200 441
[08/Mar/2018 05:05:12] INFO [django.server:124] "GET / HTTP/1.1" 200 38919
[08/Mar/2018 05:05:12] INFO [django.server:124] "GET /api/column/postList/ HTTP/1.1" 200 441
[08/Mar/2018 05:05:12] INFO [django.server:124] "GET / HTTP/1.1" 200 38919
[08/Mar/2018 05:05:13] INFO [django.server:124] "GET /api/column/postList/ HTTP/1.1" 200 441
[08/Mar/2018 05:05:13] INFO [django.server:124] "GET / HTTP/1.1" 200 38919
[08/Mar/2018 05:05:13] INFO [django.server:124] "GET /api/column/postList/ HTTP/1.1" 200 441
[08/Mar/2018 05:05:13] INFO [django.server:124] "GET / HTTP/1.1" 200 38919
[08/Mar/2018 05:05:13] INFO [django.server:124] "GET / HTTP/1.1" 200 38919
[08/Mar/2018 05:05:13] INFO [django.server:124] "GET /api/column/postList/ HTTP/1.1" 200 441
[08/Mar/2018 05:05:13] INFO [django.server:124] "GET / HTTP/1.1" 200 38919
[08/Mar/2018 05:05:13] INFO [django.server:124] "GET / HTTP/1.1" 200 38919
[08/Mar/2018 05:05:14] INFO [django.server:124] "GET /api/column/postList/ HTTP/1.1" 200 441
[08/Mar/2018 05:05:15] ERROR [django.request:135] Internal Server Error: /
Traceback (most recent call last):
  File "/Users/joohyonlee/.pyenv/versions/3.6.3/envs/docker-test/lib/python3.6/site-packages/django/core/handlers/exception.py", line 41, in inner
    response = get_response(request)
  File "/Users/joohyonlee/.pyenv/versions/3.6.3/envs/docker-test/lib/python3.6/site-packages/django/core/handlers/base.py", line 187, in _get_response
    response = self.process_exception_by_middleware(e, request)
  File "/Users/joohyonlee/.pyenv/versions/3.6.3/envs/docker-test/lib/python3.6/site-packages/django/core/handlers/base.py", line 185, in _get_response
    response = wrapped_callback(request, *callback_args, **callback_kwargs)
  File "/Users/joohyonlee/.pyenv/versions/3.6.3/envs/docker-test/lib/python3.6/site-packages/django/utils/decorators.py", line 149, in _wrapped_view
    response = view_func(request, *args, **kwargs)
  File "/Users/joohyonlee/devocto/octocolumn/octocolumn/config/views/index.py", line 18, in index
    if request.COOKIES['token']:
KeyError: 'token'
[08/Mar/2018 05:05:15] ERROR [django.server:124] "GET / HTTP/1.1" 500 27
[08/Mar/2018 05:05:16] ERROR [django.request:135] Internal Server Error: /
Traceback (most recent call last):
  File "/Users/joohyonlee/.pyenv/versions/3.6.3/envs/docker-test/lib/python3.6/site-packages/django/core/handlers/exception.py", line 41, in inner
    response = get_response(request)
  File "/Users/joohyonlee/.pyenv/versions/3.6.3/envs/docker-test/lib/python3.6/site-packages/django/core/handlers/base.py", line 187, in _get_response
    response = self.process_exception_by_middleware(e, request)
  File "/Users/joohyonlee/.pyenv/versions/3.6.3/envs/docker-test/lib/python3.6/site-packages/django/core/handlers/base.py", line 185, in _get_response
    response = wrapped_callback(request, *callback_args, **callback_kwargs)
  File "/Users/joohyonlee/.pyenv/versions/3.6.3/envs/docker-test/lib/python3.6/site-packages/django/utils/decorators.py", line 149, in _wrapped_view
    response = view_func(request, *args, **kwargs)
  File "/Users/joohyonlee/devocto/octocolumn/octocolumn/config/views/index.py", line 18, in index
    if request.COOKIES['token']:
KeyError: 'token'
[08/Mar/2018 05:05:16] ERROR [django.server:124] "GET / HTTP/1.1" 500 27
[08/Mar/2018 05:05:16] ERROR [django.request:135] Internal Server Error: /
Traceback (most recent call last):
  File "/Users/joohyonlee/.pyenv/versions/3.6.3/envs/docker-test/lib/python3.6/site-packages/django/core/handlers/exception.py", line 41, in inner
    response = get_response(request)
  File "/Users/joohyonlee/.pyenv/versions/3.6.3/envs/docker-test/lib/python3.6/site-packages/django/core/handlers/base.py", line 187, in _get_response
    response = self.process_exception_by_middleware(e, request)
  File "/Users/joohyonlee/.pyenv/versions/3.6.3/envs/docker-test/lib/python3.6/site-packages/django/core/handlers/base.py", line 185, in _get_response
    response = wrapped_callback(request, *callback_args, **callback_kwargs)
  File "/Users/joohyonlee/.pyenv/versions/3.6.3/envs/docker-test/lib/python3.6/site-packages/django/utils/decorators.py", line 149, in _wrapped_view
    response = view_func(request, *args, **kwargs)
  File "/Users/joohyonlee/devocto/octocolumn/octocolumn/config/views/index.py", line 18, in index
    if request.COOKIES['token']:
KeyError: 'token'
[08/Mar/2018 05:05:16] ERROR [django.server:124] "GET / HTTP/1.1" 500 27
[08/Mar/2018 05:05:17] ERROR [django.request:135] Internal Server Error: /
Traceback (most recent call last):
  File "/Users/joohyonlee/.pyenv/versions/3.6.3/envs/docker-test/lib/python3.6/site-packages/django/core/handlers/exception.py", line 41, in inner
    response = get_response(request)
  File "/Users/joohyonlee/.pyenv/versions/3.6.3/envs/docker-test/lib/python3.6/site-packages/django/core/handlers/base.py", line 187, in _get_response
    response = self.process_exception_by_middleware(e, request)
  File "/Users/joohyonlee/.pyenv/versions/3.6.3/envs/docker-test/lib/python3.6/site-packages/django/core/handlers/base.py", line 185, in _get_response
    response = wrapped_callback(request, *callback_args, **callback_kwargs)
  File "/Users/joohyonlee/.pyenv/versions/3.6.3/envs/docker-test/lib/python3.6/site-packages/django/utils/decorators.py", line 149, in _wrapped_view
    response = view_func(request, *args, **kwargs)
  File "/Users/joohyonlee/devocto/octocolumn/octocolumn/config/views/index.py", line 18, in index
    if request.COOKIES['token']:
KeyError: 'token'
[08/Mar/2018 05:05:17] ERROR [django.server:124] "GET / HTTP/1.1" 500 27
[08/Mar/2018 05:05:17] ERROR [django.request:135] Internal Server Error: /
Traceback (most recent call last):
  File "/Users/joohyonlee/.pyenv/versions/3.6.3/envs/docker-test/lib/python3.6/site-packages/django/core/handlers/exception.py", line 41, in inner
    response = get_response(request)
  File "/Users/joohyonlee/.pyenv/versions/3.6.3/envs/docker-test/lib/python3.6/site-packages/django/core/handlers/base.py", line 187, in _get_response
    response = self.process_exception_by_middleware(e, request)
  File "/Users/joohyonlee/.pyenv/versions/3.6.3/envs/docker-test/lib/python3.6/site-packages/django/core/handlers/base.py", line 185, in _get_response
    response = wrapped_callback(request, *callback_args, **callback_kwargs)
  File "/Users/joohyonlee/.pyenv/versions/3.6.3/envs/docker-test/lib/python3.6/site-packages/django/utils/decorators.py", line 149, in _wrapped_view
    response = view_func(request, *args, **kwargs)
  File "/Users/joohyonlee/devocto/octocolumn/octocolumn/config/views/index.py", line 18, in index
    if request.COOKIES['token']:
KeyError: 'token'
[08/Mar/2018 05:05:17] ERROR [django.server:124] "GET / HTTP/1.1" 500 27
[08/Mar/2018 05:06:11] ERROR [django.request:135] Internal Server Error: /
Traceback (most recent call last):
  File "/Users/joohyonlee/.pyenv/versions/3.6.3/envs/docker-test/lib/python3.6/site-packages/django/core/handlers/exception.py", line 41, in inner
    response = get_response(request)
  File "/Users/joohyonlee/.pyenv/versions/3.6.3/envs/docker-test/lib/python3.6/site-packages/django/core/handlers/base.py", line 187, in _get_response
    response = self.process_exception_by_middleware(e, request)
  File "/Users/joohyonlee/.pyenv/versions/3.6.3/envs/docker-test/lib/python3.6/site-packages/django/core/handlers/base.py", line 185, in _get_response
    response = wrapped_callback(request, *callback_args, **callback_kwargs)
  File "/Users/joohyonlee/.pyenv/versions/3.6.3/envs/docker-test/lib/python3.6/site-packages/django/utils/decorators.py", line 149, in _wrapped_view
    response = view_func(request, *args, **kwargs)
  File "/Users/joohyonlee/devocto/octocolumn/octocolumn/config/views/index.py", line 19, in index
    if request.COOKIES['token']:
KeyError: 'token'
[08/Mar/2018 05:06:11] ERROR [django.server:124] "GET / HTTP/1.1" 500 27
[08/Mar/2018 05:06:12] ERROR [django.request:135] Internal Server Error: /
Traceback (most recent call last):
  File "/Users/joohyonlee/.pyenv/versions/3.6.3/envs/docker-test/lib/python3.6/site-packages/django/core/handlers/exception.py", line 41, in inner
    response = get_response(request)
  File "/Users/joohyonlee/.pyenv/versions/3.6.3/envs/docker-test/lib/python3.6/site-packages/django/core/handlers/base.py", line 187, in _get_response
    response = self.process_exception_by_middleware(e, request)
  File "/Users/joohyonlee/.pyenv/versions/3.6.3/envs/docker-test/lib/python3.6/site-packages/django/core/handlers/base.py", line 185, in _get_response
    response = wrapped_callback(request, *callback_args, **callback_kwargs)
  File "/Users/joohyonlee/.pyenv/versions/3.6.3/envs/docker-test/lib/python3.6/site-packages/django/utils/decorators.py", line 149, in _wrapped_view
    response = view_func(request, *args, **kwargs)
  File "/Users/joohyonlee/devocto/octocolumn/octocolumn/config/views/index.py", line 19, in index
    if request.COOKIES['token']:
KeyError: 'token'
[08/Mar/2018 05:06:12] ERROR [django.server:124] "GET / HTTP/1.1" 500 27
[08/Mar/2018 05:06:12] ERROR [django.request:135] Internal Server Error: /
Traceback (most recent call last):
  File "/Users/joohyonlee/.pyenv/versions/3.6.3/envs/docker-test/lib/python3.6/site-packages/django/core/handlers/exception.py", line 41, in inner
    response = get_response(request)
  File "/Users/joohyonlee/.pyenv/versions/3.6.3/envs/docker-test/lib/python3.6/site-packages/django/core/handlers/base.py", line 187, in _get_response
    response = self.process_exception_by_middleware(e, request)
  File "/Users/joohyonlee/.pyenv/versions/3.6.3/envs/docker-test/lib/python3.6/site-packages/django/core/handlers/base.py", line 185, in _get_response
    response = wrapped_callback(request, *callback_args, **callback_kwargs)
  File "/Users/joohyonlee/.pyenv/versions/3.6.3/envs/docker-test/lib/python3.6/site-packages/django/utils/decorators.py", line 149, in _wrapped_view
    response = view_func(request, *args, **kwargs)
  File "/Users/joohyonlee/devocto/octocolumn/octocolumn/config/views/index.py", line 19, in index
    if request.COOKIES['token']:
KeyError: 'token'
[08/Mar/2018 05:06:12] ERROR [django.server:124] "GET / HTTP/1.1" 500 27
[08/Mar/2018 05:07:33] ERROR [django.request:135] Internal Server Error: /
Traceback (most recent call last):
  File "/Users/joohyonlee/.pyenv/versions/3.6.3/envs/docker-test/lib/python3.6/site-packages/django/core/handlers/exception.py", line 41, in inner
    response = get_response(request)
  File "/Users/joohyonlee/.pyenv/versions/3.6.3/envs/docker-test/lib/python3.6/site-packages/django/core/handlers/base.py", line 187, in _get_response
    response = self.process_exception_by_middleware(e, request)
  File "/Users/joohyonlee/.pyenv/versions/3.6.3/envs/docker-test/lib/python3.6/site-packages/django/core/handlers/base.py", line 185, in _get_response
    response = wrapped_callback(request, *callback_args, **callback_kwargs)
  File "/Users/joohyonlee/devocto/octocolumn/octocolumn/config/views/index.py", line 18, in index
    if request.COOKIES['token']:
KeyError: 'token'
[08/Mar/2018 05:07:33] ERROR [django.server:124] "GET / HTTP/1.1" 500 27
[08/Mar/2018 05:07:33] ERROR [django.request:135] Internal Server Error: /
Traceback (most recent call last):
  File "/Users/joohyonlee/.pyenv/versions/3.6.3/envs/docker-test/lib/python3.6/site-packages/django/core/handlers/exception.py", line 41, in inner
    response = get_response(request)
  File "/Users/joohyonlee/.pyenv/versions/3.6.3/envs/docker-test/lib/python3.6/site-packages/django/core/handlers/base.py", line 187, in _get_response
    response = self.process_exception_by_middleware(e, request)
  File "/Users/joohyonlee/.pyenv/versions/3.6.3/envs/docker-test/lib/python3.6/site-packages/django/core/handlers/base.py", line 185, in _get_response
    response = wrapped_callback(request, *callback_args, **callback_kwargs)
  File "/Users/joohyonlee/devocto/octocolumn/octocolumn/config/views/index.py", line 18, in index
    if request.COOKIES['token']:
KeyError: 'token'
[08/Mar/2018 05:07:33] ERROR [django.server:124] "GET / HTTP/1.1" 500 27
[08/Mar/2018 05:07:34] ERROR [django.request:135] Internal Server Error: /
Traceback (most recent call last):
  File "/Users/joohyonlee/.pyenv/versions/3.6.3/envs/docker-test/lib/python3.6/site-packages/django/core/handlers/exception.py", line 41, in inner
    response = get_response(request)
  File "/Users/joohyonlee/.pyenv/versions/3.6.3/envs/docker-test/lib/python3.6/site-packages/django/core/handlers/base.py", line 187, in _get_response
    response = self.process_exception_by_middleware(e, request)
  File "/Users/joohyonlee/.pyenv/versions/3.6.3/envs/docker-test/lib/python3.6/site-packages/django/core/handlers/base.py", line 185, in _get_response
    response = wrapped_callback(request, *callback_args, **callback_kwargs)
  File "/Users/joohyonlee/devocto/octocolumn/octocolumn/config/views/index.py", line 18, in index
    if request.COOKIES['token']:
KeyError: 'token'
[08/Mar/2018 05:07:34] ERROR [django.server:124] "GET / HTTP/1.1" 500 27
[08/Mar/2018 05:07:34] ERROR [django.request:135] Internal Server Error: /
Traceback (most recent call last):
  File "/Users/joohyonlee/.pyenv/versions/3.6.3/envs/docker-test/lib/python3.6/site-packages/django/core/handlers/exception.py", line 41, in inner
    response = get_response(request)
  File "/Users/joohyonlee/.pyenv/versions/3.6.3/envs/docker-test/lib/python3.6/site-packages/django/core/handlers/base.py", line 187, in _get_response
    response = self.process_exception_by_middleware(e, request)
  File "/Users/joohyonlee/.pyenv/versions/3.6.3/envs/docker-test/lib/python3.6/site-packages/django/core/handlers/base.py", line 185, in _get_response
    response = wrapped_callback(request, *callback_args, **callback_kwargs)
  File "/Users/joohyonlee/devocto/octocolumn/octocolumn/config/views/index.py", line 18, in index
    if request.COOKIES['token']:
KeyError: 'token'
[08/Mar/2018 05:07:34] ERROR [django.server:124] "GET / HTTP/1.1" 500 27
[08/Mar/2018 05:07:34] ERROR [django.request:135] Internal Server Error: /
Traceback (most recent call last):
  File "/Users/joohyonlee/.pyenv/versions/3.6.3/envs/docker-test/lib/python3.6/site-packages/django/core/handlers/exception.py", line 41, in inner
    response = get_response(request)
  File "/Users/joohyonlee/.pyenv/versions/3.6.3/envs/docker-test/lib/python3.6/site-packages/django/core/handlers/base.py", line 187, in _get_response
    response = self.process_exception_by_middleware(e, request)
  File "/Users/joohyonlee/.pyenv/versions/3.6.3/envs/docker-test/lib/python3.6/site-packages/django/core/handlers/base.py", line 185, in _get_response
    response = wrapped_callback(request, *callback_args, **callback_kwargs)
  File "/Users/joohyonlee/devocto/octocolumn/octocolumn/config/views/index.py", line 18, in index
    if request.COOKIES['token']:
KeyError: 'token'
[08/Mar/2018 05:07:34] ERROR [django.server:124] "GET / HTTP/1.1" 500 27
[08/Mar/2018 05:07:34] ERROR [django.request:135] Internal Server Error: /
Traceback (most recent call last):
  File "/Users/joohyonlee/.pyenv/versions/3.6.3/envs/docker-test/lib/python3.6/site-packages/django/core/handlers/exception.py", line 41, in inner
    response = get_response(request)
  File "/Users/joohyonlee/.pyenv/versions/3.6.3/envs/docker-test/lib/python3.6/site-packages/django/core/handlers/base.py", line 187, in _get_response
    response = self.process_exception_by_middleware(e, request)
  File "/Users/joohyonlee/.pyenv/versions/3.6.3/envs/docker-test/lib/python3.6/site-packages/django/core/handlers/base.py", line 185, in _get_response
    response = wrapped_callback(request, *callback_args, **callback_kwargs)
  File "/Users/joohyonlee/devocto/octocolumn/octocolumn/config/views/index.py", line 18, in index
    if request.COOKIES['token']:
KeyError: 'token'
[08/Mar/2018 05:07:34] ERROR [django.server:124] "GET / HTTP/1.1" 500 27
[08/Mar/2018 05:07:57] ERROR [django.request:135] Internal Server Error: /
Traceback (most recent call last):
  File "/Users/joohyonlee/.pyenv/versions/3.6.3/envs/docker-test/lib/python3.6/site-packages/django/core/handlers/exception.py", line 41, in inner
    response = get_response(request)
  File "/Users/joohyonlee/.pyenv/versions/3.6.3/envs/docker-test/lib/python3.6/site-packages/django/core/handlers/base.py", line 187, in _get_response
    response = self.process_exception_by_middleware(e, request)
  File "/Users/joohyonlee/.pyenv/versions/3.6.3/envs/docker-test/lib/python3.6/site-packages/django/core/handlers/base.py", line 185, in _get_response
    response = wrapped_callback(request, *callback_args, **callback_kwargs)
  File "/Users/joohyonlee/devocto/octocolumn/octocolumn/config/views/index.py", line 18, in index
    if request.COOKIES['token'] is None:
KeyError: 'token'
[08/Mar/2018 05:07:57] ERROR [django.server:124] "GET / HTTP/1.1" 500 27
[08/Mar/2018 05:07:57] ERROR [django.request:135] Internal Server Error: /
Traceback (most recent call last):
  File "/Users/joohyonlee/.pyenv/versions/3.6.3/envs/docker-test/lib/python3.6/site-packages/django/core/handlers/exception.py", line 41, in inner
    response = get_response(request)
  File "/Users/joohyonlee/.pyenv/versions/3.6.3/envs/docker-test/lib/python3.6/site-packages/django/core/handlers/base.py", line 187, in _get_response
    response = self.process_exception_by_middleware(e, request)
  File "/Users/joohyonlee/.pyenv/versions/3.6.3/envs/docker-test/lib/python3.6/site-packages/django/core/handlers/base.py", line 185, in _get_response
    response = wrapped_callback(request, *callback_args, **callback_kwargs)
  File "/Users/joohyonlee/devocto/octocolumn/octocolumn/config/views/index.py", line 18, in index
    if request.COOKIES['token'] is None:
KeyError: 'token'
[08/Mar/2018 05:07:57] ERROR [django.server:124] "GET / HTTP/1.1" 500 27
[08/Mar/2018 05:07:58] ERROR [django.request:135] Internal Server Error: /
Traceback (most recent call last):
  File "/Users/joohyonlee/.pyenv/versions/3.6.3/envs/docker-test/lib/python3.6/site-packages/django/core/handlers/exception.py", line 41, in inner
    response = get_response(request)
  File "/Users/joohyonlee/.pyenv/versions/3.6.3/envs/docker-test/lib/python3.6/site-packages/django/core/handlers/base.py", line 187, in _get_response
    response = self.process_exception_by_middleware(e, request)
  File "/Users/joohyonlee/.pyenv/versions/3.6.3/envs/docker-test/lib/python3.6/site-packages/django/core/handlers/base.py", line 185, in _get_response
    response = wrapped_callback(request, *callback_args, **callback_kwargs)
  File "/Users/joohyonlee/devocto/octocolumn/octocolumn/config/views/index.py", line 18, in index
    if request.COOKIES['token'] is None:
KeyError: 'token'
[08/Mar/2018 05:07:58] ERROR [django.server:124] "GET / HTTP/1.1" 500 27
[08/Mar/2018 05:07:58] ERROR [django.request:135] Internal Server Error: /
Traceback (most recent call last):
  File "/Users/joohyonlee/.pyenv/versions/3.6.3/envs/docker-test/lib/python3.6/site-packages/django/core/handlers/exception.py", line 41, in inner
    response = get_response(request)
  File "/Users/joohyonlee/.pyenv/versions/3.6.3/envs/docker-test/lib/python3.6/site-packages/django/core/handlers/base.py", line 187, in _get_response
    response = self.process_exception_by_middleware(e, request)
  File "/Users/joohyonlee/.pyenv/versions/3.6.3/envs/docker-test/lib/python3.6/site-packages/django/core/handlers/base.py", line 185, in _get_response
    response = wrapped_callback(request, *callback_args, **callback_kwargs)
  File "/Users/joohyonlee/devocto/octocolumn/octocolumn/config/views/index.py", line 18, in index
    if request.COOKIES['token'] is None:
KeyError: 'token'
[08/Mar/2018 05:07:58] ERROR [django.server:124] "GET / HTTP/1.1" 500 27
[08/Mar/2018 05:07:58] ERROR [django.request:135] Internal Server Error: /
Traceback (most recent call last):
  File "/Users/joohyonlee/.pyenv/versions/3.6.3/envs/docker-test/lib/python3.6/site-packages/django/core/handlers/exception.py", line 41, in inner
    response = get_response(request)
  File "/Users/joohyonlee/.pyenv/versions/3.6.3/envs/docker-test/lib/python3.6/site-packages/django/core/handlers/base.py", line 187, in _get_response
    response = self.process_exception_by_middleware(e, request)
  File "/Users/joohyonlee/.pyenv/versions/3.6.3/envs/docker-test/lib/python3.6/site-packages/django/core/handlers/base.py", line 185, in _get_response
    response = wrapped_callback(request, *callback_args, **callback_kwargs)
  File "/Users/joohyonlee/devocto/octocolumn/octocolumn/config/views/index.py", line 18, in index
    if request.COOKIES['token'] is None:
KeyError: 'token'
[08/Mar/2018 05:07:58] ERROR [django.server:124] "GET / HTTP/1.1" 500 27
[08/Mar/2018 05:07:59] ERROR [django.request:135] Internal Server Error: /
Traceback (most recent call last):
  File "/Users/joohyonlee/.pyenv/versions/3.6.3/envs/docker-test/lib/python3.6/site-packages/django/core/handlers/exception.py", line 41, in inner
    response = get_response(request)
  File "/Users/joohyonlee/.pyenv/versions/3.6.3/envs/docker-test/lib/python3.6/site-packages/django/core/handlers/base.py", line 187, in _get_response
    response = self.process_exception_by_middleware(e, request)
  File "/Users/joohyonlee/.pyenv/versions/3.6.3/envs/docker-test/lib/python3.6/site-packages/django/core/handlers/base.py", line 185, in _get_response
    response = wrapped_callback(request, *callback_args, **callback_kwargs)
  File "/Users/joohyonlee/devocto/octocolumn/octocolumn/config/views/index.py", line 18, in index
    if request.COOKIES['token'] is None:
KeyError: 'token'
[08/Mar/2018 05:07:59] ERROR [django.server:124] "GET / HTTP/1.1" 500 27
[08/Mar/2018 05:09:11] ERROR [django.request:135] Internal Server Error: /
Traceback (most recent call last):
  File "/Users/joohyonlee/.pyenv/versions/3.6.3/envs/docker-test/lib/python3.6/site-packages/django/core/handlers/exception.py", line 41, in inner
    response = get_response(request)
  File "/Users/joohyonlee/.pyenv/versions/3.6.3/envs/docker-test/lib/python3.6/site-packages/django/core/handlers/base.py", line 187, in _get_response
    response = self.process_exception_by_middleware(e, request)
  File "/Users/joohyonlee/.pyenv/versions/3.6.3/envs/docker-test/lib/python3.6/site-packages/django/core/handlers/base.py", line 185, in _get_response
    response = wrapped_callback(request, *callback_args, **callback_kwargs)
  File "/Users/joohyonlee/devocto/octocolumn/octocolumn/config/views/index.py", line 16, in index
    if request.COOKIES['token']:
KeyError: 'token'
[08/Mar/2018 05:09:11] ERROR [django.server:124] "GET / HTTP/1.1" 500 27
[08/Mar/2018 05:09:11] ERROR [django.request:135] Internal Server Error: /
Traceback (most recent call last):
  File "/Users/joohyonlee/.pyenv/versions/3.6.3/envs/docker-test/lib/python3.6/site-packages/django/core/handlers/exception.py", line 41, in inner
    response = get_response(request)
  File "/Users/joohyonlee/.pyenv/versions/3.6.3/envs/docker-test/lib/python3.6/site-packages/django/core/handlers/base.py", line 187, in _get_response
    response = self.process_exception_by_middleware(e, request)
  File "/Users/joohyonlee/.pyenv/versions/3.6.3/envs/docker-test/lib/python3.6/site-packages/django/core/handlers/base.py", line 185, in _get_response
    response = wrapped_callback(request, *callback_args, **callback_kwargs)
  File "/Users/joohyonlee/devocto/octocolumn/octocolumn/config/views/index.py", line 16, in index
    if request.COOKIES['token']:
KeyError: 'token'
[08/Mar/2018 05:09:11] ERROR [django.server:124] "GET / HTTP/1.1" 500 27
[08/Mar/2018 05:21:56] INFO [django.server:124] "GET / HTTP/1.1" 200 38919
[08/Mar/2018 05:21:57] INFO [django.server:124] "GET /api/column/postList/ HTTP/1.1" 200 441
[08/Mar/2018 05:21:57] INFO [django.server:124] "GET / HTTP/1.1" 200 38919
[08/Mar/2018 05:21:57] INFO [django.server:124] "GET /api/column/postList/ HTTP/1.1" 200 441
[08/Mar/2018 05:22:01] ERROR [django.request:135] Internal Server Error: /api/column/post-isbuy/1
Traceback (most recent call last):
  File "/Users/joohyonlee/.pyenv/versions/3.6.3/envs/docker-test/lib/python3.6/site-packages/django/core/handlers/exception.py", line 41, in inner
    response = get_response(request)
  File "/Users/joohyonlee/.pyenv/versions/3.6.3/envs/docker-test/lib/python3.6/site-packages/django/core/handlers/base.py", line 187, in _get_response
    response = self.process_exception_by_middleware(e, request)
  File "/Users/joohyonlee/.pyenv/versions/3.6.3/envs/docker-test/lib/python3.6/site-packages/django/core/handlers/base.py", line 185, in _get_response
    response = wrapped_callback(request, *callback_args, **callback_kwargs)
  File "/Users/joohyonlee/.pyenv/versions/3.6.3/envs/docker-test/lib/python3.6/site-packages/django/views/decorators/csrf.py", line 58, in wrapped_view
    return view_func(*args, **kwargs)
  File "/Users/joohyonlee/.pyenv/versions/3.6.3/envs/docker-test/lib/python3.6/site-packages/django/views/generic/base.py", line 68, in view
    return self.dispatch(request, *args, **kwargs)
  File "/Users/joohyonlee/.pyenv/versions/3.6.3/envs/docker-test/lib/python3.6/site-packages/rest_framework/views.py", line 494, in dispatch
    response = self.handle_exception(exc)
  File "/Users/joohyonlee/.pyenv/versions/3.6.3/envs/docker-test/lib/python3.6/site-packages/rest_framework/views.py", line 454, in handle_exception
    self.raise_uncaught_exception(exc)
  File "/Users/joohyonlee/.pyenv/versions/3.6.3/envs/docker-test/lib/python3.6/site-packages/rest_framework/views.py", line 491, in dispatch
    response = handler(request, *args, **kwargs)
  File "/Users/joohyonlee/devocto/octocolumn/octocolumn/column/apis/post.py", line 325, in get
    BuyList.objects.filter(user=self.request.user, post=param).get()
  File "/Users/joohyonlee/.pyenv/versions/3.6.3/envs/docker-test/lib/python3.6/site-packages/django/db/models/manager.py", line 85, in manager_method
    return getattr(self.get_queryset(), name)(*args, **kwargs)
  File "/Users/joohyonlee/.pyenv/versions/3.6.3/envs/docker-test/lib/python3.6/site-packages/django/db/models/query.py", line 784, in filter
    return self._filter_or_exclude(False, *args, **kwargs)
  File "/Users/joohyonlee/.pyenv/versions/3.6.3/envs/docker-test/lib/python3.6/site-packages/django/db/models/query.py", line 802, in _filter_or_exclude
    clone.query.add_q(Q(*args, **kwargs))
  File "/Users/joohyonlee/.pyenv/versions/3.6.3/envs/docker-test/lib/python3.6/site-packages/django/db/models/sql/query.py", line 1250, in add_q
    clause, _ = self._add_q(q_object, self.used_aliases)
  File "/Users/joohyonlee/.pyenv/versions/3.6.3/envs/docker-test/lib/python3.6/site-packages/django/db/models/sql/query.py", line 1276, in _add_q
    allow_joins=allow_joins, split_subq=split_subq,
  File "/Users/joohyonlee/.pyenv/versions/3.6.3/envs/docker-test/lib/python3.6/site-packages/django/db/models/sql/query.py", line 1206, in build_filter
    condition = lookup_class(lhs, value)
  File "/Users/joohyonlee/.pyenv/versions/3.6.3/envs/docker-test/lib/python3.6/site-packages/django/db/models/lookups.py", line 24, in __init__
    self.rhs = self.get_prep_lookup()
  File "/Users/joohyonlee/.pyenv/versions/3.6.3/envs/docker-test/lib/python3.6/site-packages/django/db/models/fields/related_lookups.py", line 112, in get_prep_lookup
    self.rhs = target_field.get_prep_value(self.rhs)
  File "/Users/joohyonlee/.pyenv/versions/3.6.3/envs/docker-test/lib/python3.6/site-packages/django/db/models/fields/__init__.py", line 966, in get_prep_value
    return int(value)
TypeError: int() argument must be a string, a bytes-like object or a number, not 'AnonymousUser'
[08/Mar/2018 05:22:01] ERROR [django.server:124] "GET /api/column/post-isbuy/1 HTTP/1.1" 500 27
[08/Mar/2018 05:22:15] INFO [django.server:124] "GET / HTTP/1.1" 200 38919
[08/Mar/2018 05:22:15] INFO [django.server:124] "GET /api/column/postList/ HTTP/1.1" 200 441
[08/Mar/2018 05:22:38] WARNING [django.server:124] "POST /api/member/login/ HTTP/1.1" 401 32
[08/Mar/2018 05:22:49] WARNING [django.server:124] "POST /api/member/login/ HTTP/1.1" 401 32
[08/Mar/2018 05:22:59] INFO [django.server:124] "POST /api/member/login/ HTTP/1.1" 200 334
[08/Mar/2018 05:22:59] INFO [django.server:124] "GET / HTTP/1.1" 200 38538
[08/Mar/2018 05:22:59] INFO [django.server:124] "GET /api/column/postList/ HTTP/1.1" 200 441
[08/Mar/2018 05:22:59] INFO [django.server:124] "POST /api/member/userInfo/ HTTP/1.1" 200 142
[08/Mar/2018 05:23:02] INFO [django.server:124] "GET /api/column/post-isbuy/1 HTTP/1.1" 200 25
[08/Mar/2018 05:23:02] INFO [django.server:124] "GET /read/1 HTTP/1.1" 200 12502
[08/Mar/2018 05:23:22] INFO [django.server:124] "POST /api/member/userInfo/ HTTP/1.1" 200 142
[08/Mar/2018 05:31:09] INFO [django.server:124] "GET / HTTP/1.1" 200 38538
[08/Mar/2018 05:31:10] INFO [django.server:124] "GET /api/column/postList/ HTTP/1.1" 200 441
[08/Mar/2018 05:31:10] INFO [django.server:124] "POST /api/member/userInfo/ HTTP/1.1" 200 142
[08/Mar/2018 05:31:11] INFO [django.server:124] "GET /api/column/post-isbuy/1 HTTP/1.1" 200 25
[08/Mar/2018 05:31:11] INFO [django.server:124] "GET /read/1 HTTP/1.1" 200 12502
[08/Mar/2018 05:31:18] INFO [django.server:124] "POST /api/member/userInfo/ HTTP/1.1" 200 142
[08/Mar/2018 05:33:11] INFO [django.server:124] "GET /api/column/post-isbuy/1 HTTP/1.1" 200 25
[08/Mar/2018 05:33:11] INFO [django.server:124] "GET /read/1 HTTP/1.1" 200 12502
[08/Mar/2018 05:43:57] INFO [django.server:124] "GET /read/1 HTTP/1.1" 200 12502
[08/Mar/2018 05:43:58] INFO [django.server:124] "GET /read/1 HTTP/1.1" 200 12502
[08/Mar/2018 05:43:58] INFO [django.server:124] "GET /read/1 HTTP/1.1" 200 12502
[08/Mar/2018 05:46:54] WARNING [django.server:124] "GET /api/column/commentList/2 HTTP/1.1" 401 60
[08/Mar/2018 05:47:02] INFO [django.server:124] "POST /api/member/login/ HTTP/1.1" 200 334
[08/Mar/2018 05:47:05] WARNING [django.server:124] "GET /api/column/commentList/2 HTTP/1.1" 401 60
[08/Mar/2018 05:47:10] WARNING [django.request:152] Not Found: /api/column/commentList/
[08/Mar/2018 05:47:10] WARNING [django.server:124] "GET /api/column/commentList/ HTTP/1.1" 404 97
[08/Mar/2018 05:47:14] INFO [django.server:124] "POST /api/column/temp/ HTTP/1.1" 201 22
[08/Mar/2018 05:48:02] INFO [django.server:124] "GET /write/ HTTP/1.1" 200 28188
[08/Mar/2018 05:48:04] INFO [django.server:124] "POST /api/column/isauthor/ HTTP/1.1" 200 15
[08/Mar/2018 05:48:18] INFO [django.server:124] "POST /api/column/temp/ HTTP/1.1" 201 22
[08/Mar/2018 05:48:32] INFO [django.server:124] "POST /api/column/temp/ HTTP/1.1" 200 24
[08/Mar/2018 05:48:40] WARNING [django.server:124] "POST /api/column/tmpimageupload/ HTTP/1.1" 401 49
[08/Mar/2018 05:48:47] INFO [django.server:124] "GET /write/ HTTP/1.1" 200 28188
[08/Mar/2018 05:48:47] INFO [django.server:124] "POST /api/column/isauthor/ HTTP/1.1" 200 15
[08/Mar/2018 05:48:50] INFO [django.server:124] "GET /write/ HTTP/1.1" 200 28188
[08/Mar/2018 05:48:51] INFO [django.server:124] "POST /api/column/isauthor/ HTTP/1.1" 200 15
[08/Mar/2018 05:49:00] INFO [django.server:124] "GET / HTTP/1.1" 200 38538
[08/Mar/2018 05:49:01] INFO [django.server:124] "GET /api/column/postList/ HTTP/1.1" 200 441
[08/Mar/2018 05:49:01] INFO [django.server:124] "POST /api/member/userInfo/ HTTP/1.1" 200 142
[08/Mar/2018 05:49:06] INFO [django.server:124] "GET /write/ HTTP/1.1" 200 28188
[08/Mar/2018 05:49:25] INFO [django.server:124] "GET / HTTP/1.1" 200 38919
[08/Mar/2018 05:49:25] INFO [django.server:124] "GET /api/column/postList/ HTTP/1.1" 200 441
[08/Mar/2018 05:49:38] WARNING [django.server:124] "POST /api/member/login/ HTTP/1.1" 401 32
[08/Mar/2018 05:49:51] WARNING [django.server:124] "POST /api/member/login/ HTTP/1.1" 401 32
[08/Mar/2018 05:50:18] WARNING [django.server:124] "POST /api/member/login/ HTTP/1.1" 401 32
[08/Mar/2018 05:50:30] WARNING [django.server:124] "POST /api/member/login/ HTTP/1.1" 401 32
[08/Mar/2018 05:50:31] INFO [django.server:124] "GET / HTTP/1.1" 200 38919
[08/Mar/2018 05:50:32] INFO [django.server:124] "GET /api/column/postList/ HTTP/1.1" 200 441
[08/Mar/2018 05:50:32] INFO [django.server:124] "GET / HTTP/1.1" 200 38919
[08/Mar/2018 05:50:32] INFO [django.server:124] "GET /api/column/postList/ HTTP/1.1" 200 441
[08/Mar/2018 05:50:32] INFO [django.server:124] "GET / HTTP/1.1" 200 38919
[08/Mar/2018 05:50:32] INFO [django.server:124] "GET /api/column/postList/ HTTP/1.1" 200 441
[08/Mar/2018 05:50:50] INFO [django.server:124] "POST /api/member/login/ HTTP/1.1" 200 334
[08/Mar/2018 05:50:50] INFO [django.server:124] "GET / HTTP/1.1" 200 38538
[08/Mar/2018 05:50:50] INFO [django.server:124] "GET /api/column/postList/ HTTP/1.1" 200 441
[08/Mar/2018 05:50:50] INFO [django.server:124] "POST /api/member/userInfo/ HTTP/1.1" 200 142
[08/Mar/2018 05:50:57] INFO [django.server:124] "POST /api/column/isauthor/ HTTP/1.1" 200 15
[08/Mar/2018 05:51:27] WARNING [django.server:124] "POST /api/column/tmpimageupload/ HTTP/1.1" 401 49
[08/Mar/2018 05:52:09] INFO [django.server:124] "POST /api/column/temp/ HTTP/1.1" 201 22
[08/Mar/2018 05:52:18] INFO [django.server:124] "POST /api/column/temp/ HTTP/1.1" 200 24
[08/Mar/2018 05:52:32] INFO [django.server:124] "POST /api/column/post-create/ HTTP/1.1" 201 32
[08/Mar/2018 05:52:41] INFO [django.server:124] "GET /write/ HTTP/1.1" 200 28188
[08/Mar/2018 05:52:42] INFO [django.server:124] "POST /api/column/isauthor/ HTTP/1.1" 200 15
[08/Mar/2018 05:52:43] INFO [django.server:124] "GET /write/ HTTP/1.1" 200 28188
[08/Mar/2018 05:52:44] INFO [django.server:124] "POST /api/column/isauthor/ HTTP/1.1" 200 15
[08/Mar/2018 05:52:47] INFO [django.server:124] "GET / HTTP/1.1" 200 38538
[08/Mar/2018 05:52:48] INFO [django.server:124] "GET /api/column/postList/ HTTP/1.1" 200 3325
[08/Mar/2018 05:52:48] INFO [django.server:124] "POST /api/member/userInfo/ HTTP/1.1" 200 142
[08/Mar/2018 05:52:50] INFO [django.server:124] "GET /api/column/post-isbuy/2 HTTP/1.1" 200 137
[08/Mar/2018 05:52:58] INFO [django.server:124] "GET / HTTP/1.1" 200 38538
[08/Mar/2018 05:52:59] INFO [django.server:124] "GET /api/column/postList/ HTTP/1.1" 200 3325
[08/Mar/2018 05:52:59] INFO [django.server:124] "POST /api/member/userInfo/ HTTP/1.1" 200 142
[08/Mar/2018 05:53:26] INFO [django.server:124] "GET /write/ HTTP/1.1" 200 28188
[08/Mar/2018 05:53:27] INFO [django.server:124] "POST /api/column/isauthor/ HTTP/1.1" 200 15
[08/Mar/2018 05:53:43] INFO [django.server:124] "POST /api/column/temp/ HTTP/1.1" 201 22
[08/Mar/2018 05:54:00] INFO [django.server:124] "POST /api/column/temp/ HTTP/1.1" 200 24
[08/Mar/2018 05:54:12] INFO [django.server:124] "POST /api/column/post-create/ HTTP/1.1" 201 32
[08/Mar/2018 05:54:22] INFO [django.server:124] "GET / HTTP/1.1" 200 38538
[08/Mar/2018 05:54:23] INFO [django.server:124] "GET /api/column/postList/ HTTP/1.1" 200 6264
[08/Mar/2018 05:54:23] INFO [django.server:124] "POST /api/member/userInfo/ HTTP/1.1" 200 142
[08/Mar/2018 05:54:30] INFO [django.server:124] "GET /write/ HTTP/1.1" 200 28188
[08/Mar/2018 05:54:31] INFO [django.server:124] "POST /api/column/isauthor/ HTTP/1.1" 200 15
[08/Mar/2018 05:55:21] INFO [django.server:124] "POST /api/column/temp/ HTTP/1.1" 201 22
[08/Mar/2018 05:55:34] INFO [django.server:124] "POST /api/column/temp/ HTTP/1.1" 200 24
[08/Mar/2018 05:57:24] WARNING [django.server:124] "POST /api/column/tmpimageupload/ HTTP/1.1" 401 49
[08/Mar/2018 05:57:42] INFO [django.server:124] "POST /api/column/temp/ HTTP/1.1" 200 24
[08/Mar/2018 05:57:48] INFO [django.server:124] "POST /api/column/post-create/ HTTP/1.1" 201 32
[08/Mar/2018 05:57:51] INFO [django.server:124] "GET /write/ HTTP/1.1" 200 28188
[08/Mar/2018 05:57:51] INFO [django.server:124] "POST /api/column/isauthor/ HTTP/1.1" 200 15
[08/Mar/2018 05:57:54] INFO [django.server:124] "GET / HTTP/1.1" 200 38538
[08/Mar/2018 05:57:54] INFO [django.server:124] "GET /api/column/postList/ HTTP/1.1" 200 8732
[08/Mar/2018 05:57:54] INFO [django.server:124] "POST /api/member/userInfo/ HTTP/1.1" 200 142
[08/Mar/2018 05:59:07] INFO [django.server:124] "GET /write/ HTTP/1.1" 200 28188
[08/Mar/2018 05:59:09] INFO [django.server:124] "POST /api/column/isauthor/ HTTP/1.1" 200 15
[08/Mar/2018 05:59:14] INFO [django.server:124] "POST /api/column/temp/ HTTP/1.1" 201 22
[08/Mar/2018 05:59:20] INFO [django.server:124] "POST /api/column/temp/ HTTP/1.1" 200 24
[08/Mar/2018 06:00:23] WARNING [django.server:124] "POST /api/column/tmpimageupload/ HTTP/1.1" 401 49
[08/Mar/2018 06:00:40] INFO [django.server:124] "POST /api/column/temp/ HTTP/1.1" 200 24
[08/Mar/2018 06:00:47] INFO [django.server:124] "POST /api/column/post-create/ HTTP/1.1" 201 32
[08/Mar/2018 06:00:54] INFO [django.server:124] "GET / HTTP/1.1" 200 38538
[08/Mar/2018 06:00:54] INFO [django.server:124] "GET /api/column/postList/ HTTP/1.1" 200 11658
[08/Mar/2018 06:00:54] INFO [django.server:124] "POST /api/member/userInfo/ HTTP/1.1" 200 142
[08/Mar/2018 06:06:11] INFO [django.server:124] "GET /write/ HTTP/1.1" 200 28188
[08/Mar/2018 06:06:13] INFO [django.server:124] "POST /api/column/isauthor/ HTTP/1.1" 200 15
[08/Mar/2018 06:06:26] WARNING [django.server:124] "POST /api/column/tmpimageupload/ HTTP/1.1" 401 49
[09/Mar/2018 10:56:23] INFO [django.server:124] "GET / HTTP/1.1" 200 38830
[09/Mar/2018 10:56:24] INFO [django.server:124] "GET /api/column/postList/ HTTP/1.1" 200 11658
[09/Mar/2018 10:56:25] WARNING [django.request:152] Not Found: /favicon.ico
[09/Mar/2018 10:56:25] WARNING [django.server:124] "GET /favicon.ico HTTP/1.1" 404 85
[09/Mar/2018 10:56:33] WARNING [django.server:124] "POST /api/member/login/ HTTP/1.1" 401 32
[09/Mar/2018 10:56:35] WARNING [django.server:124] "POST /api/member/login/ HTTP/1.1" 401 32
[09/Mar/2018 10:56:37] WARNING [django.server:124] "POST /api/member/login/ HTTP/1.1" 401 32
[09/Mar/2018 10:56:51] WARNING [django.server:124] "POST /api/member/login/ HTTP/1.1" 401 32
[09/Mar/2018 10:56:52] WARNING [django.server:124] "POST /api/member/login/ HTTP/1.1" 401 32
[09/Mar/2018 10:56:54] WARNING [django.server:124] "POST /api/member/login/ HTTP/1.1" 401 32
[09/Mar/2018 10:56:55] WARNING [django.server:124] "POST /api/member/login/ HTTP/1.1" 401 32
[09/Mar/2018 10:56:56] WARNING [django.server:124] "POST /api/member/login/ HTTP/1.1" 401 32
[09/Mar/2018 10:57:04] INFO [django.server:124] "POST /api/member/login/ HTTP/1.1" 200 334
[09/Mar/2018 10:57:04] INFO [django.server:124] "GET / HTTP/1.1" 200 38700
[09/Mar/2018 10:57:05] INFO [django.server:124] "GET /api/column/postList/ HTTP/1.1" 200 11658
[09/Mar/2018 10:57:05] INFO [django.server:124] "POST /api/member/userInfo/ HTTP/1.1" 200 142
[09/Mar/2018 10:57:09] INFO [django.server:124] "GET /write/ HTTP/1.1" 200 27515
[09/Mar/2018 10:57:11] INFO [django.server:124] "POST /api/column/isauthor/ HTTP/1.1" 200 15
[09/Mar/2018 10:57:11] INFO [django.server:124] "POST /api/member/userInfo/ HTTP/1.1" 200 142
[09/Mar/2018 10:57:20] WARNING [django.server:124] "POST /api/column/tmpimageupload/ HTTP/1.1" 401 49
[09/Mar/2018 11:00:02] INFO [django.server:124] "GET /write/ HTTP/1.1" 200 27515
[09/Mar/2018 11:00:06] INFO [django.server:124] "POST /api/column/isauthor/ HTTP/1.1" 200 15
[09/Mar/2018 11:00:06] INFO [django.server:124] "POST /api/member/userInfo/ HTTP/1.1" 200 142
[09/Mar/2018 11:00:06] INFO [django.server:124] "GET /write/ HTTP/1.1" 200 27515
[09/Mar/2018 11:00:06] INFO [django.server:124] "POST /api/column/isauthor/ HTTP/1.1" 200 15
[09/Mar/2018 11:00:06] INFO [django.server:124] "POST /api/member/userInfo/ HTTP/1.1" 200 142
[09/Mar/2018 11:00:27] WARNING [django.server:124] "POST /api/column/tmpimageupload/ HTTP/1.1" 401 49
[09/Mar/2018 11:00:42] INFO [django.server:124] "GET /write/ HTTP/1.1" 200 27515
[09/Mar/2018 11:00:42] INFO [django.server:124] "POST /api/column/isauthor/ HTTP/1.1" 200 15
[09/Mar/2018 11:00:42] INFO [django.server:124] "POST /api/member/userInfo/ HTTP/1.1" 200 142
[09/Mar/2018 11:00:49] WARNING [django.server:124] "POST /api/column/tmpimageupload/ HTTP/1.1" 401 49
[09/Mar/2018 11:11:57] INFO [django.server:124] "GET /write/ HTTP/1.1" 200 27515
[09/Mar/2018 11:11:57] INFO [django.server:124] "POST /api/column/isauthor/ HTTP/1.1" 200 15
[09/Mar/2018 11:11:57] INFO [django.server:124] "POST /api/member/userInfo/ HTTP/1.1" 200 142
[09/Mar/2018 11:12:10] WARNING [django.server:124] "POST /api/column/tmpimageupload/ HTTP/1.1" 401 49
[09/Mar/2018 11:12:28] INFO [django.server:124] "GET /write/ HTTP/1.1" 200 27515
[09/Mar/2018 11:12:29] INFO [django.server:124] "POST /api/column/isauthor/ HTTP/1.1" 200 15
[09/Mar/2018 11:12:29] INFO [django.server:124] "POST /api/member/userInfo/ HTTP/1.1" 200 142
[09/Mar/2018 11:12:29] INFO [django.server:124] "GET /write/ HTTP/1.1" 200 27515
[09/Mar/2018 11:12:29] INFO [django.server:124] "POST /api/column/isauthor/ HTTP/1.1" 200 15
[09/Mar/2018 11:12:29] INFO [django.server:124] "POST /api/member/userInfo/ HTTP/1.1" 200 142
[09/Mar/2018 11:12:29] INFO [django.server:124] "GET /write/ HTTP/1.1" 200 27515
[09/Mar/2018 11:12:30] INFO [django.server:124] "GET /write/ HTTP/1.1" 200 27515
[09/Mar/2018 11:12:30] INFO [django.server:124] "GET /write/ HTTP/1.1" 200 27515
[09/Mar/2018 11:12:30] INFO [django.server:124] "GET /write/ HTTP/1.1" 200 27515
[09/Mar/2018 11:12:30] INFO [django.server:124] "POST /api/column/isauthor/ HTTP/1.1" 200 15
[09/Mar/2018 11:12:30] INFO [django.server:124] "POST /api/member/userInfo/ HTTP/1.1" 200 142
[09/Mar/2018 11:13:32] INFO [django.server:124] "OPTIONS /api/column/tmpimageupload/ HTTP/1.1" 200 0
[09/Mar/2018 11:13:32] WARNING [django.server:124] "POST /api/column/tmpimageupload/ HTTP/1.1" 401 49
[09/Mar/2018 11:13:56] WARNING [django.server:124] "POST /api/column/tmpimageupload/ HTTP/1.1" 401 49
[09/Mar/2018 11:17:12] WARNING [django.server:124] "POST /api/column/tmpimageupload/ HTTP/1.1" 401 49
[09/Mar/2018 11:17:28] ERROR [django.request:135] Internal Server Error: /
Traceback (most recent call last):
  File "/Users/joohyonlee/.pyenv/versions/3.6.3/envs/docker-test/lib/python3.6/site-packages/django/core/handlers/exception.py", line 41, in inner
    response = get_response(request)
  File "/Users/joohyonlee/.pyenv/versions/3.6.3/envs/docker-test/lib/python3.6/site-packages/django/core/handlers/base.py", line 187, in _get_response
    response = self.process_exception_by_middleware(e, request)
  File "/Users/joohyonlee/.pyenv/versions/3.6.3/envs/docker-test/lib/python3.6/site-packages/django/core/handlers/base.py", line 185, in _get_response
    response = wrapped_callback(request, *callback_args, **callback_kwargs)
  File "/Users/joohyonlee/devocto/octocolumn/octocolumn/config/views/index.py", line 16, in index
    if request.COOKIES['token']:
KeyError: 'token'
[09/Mar/2018 11:17:28] ERROR [django.server:124] "GET / HTTP/1.1" 500 27
[09/Mar/2018 11:17:28] WARNING [django.request:152] Not Found: /favicon.ico
[09/Mar/2018 11:17:28] WARNING [django.server:124] "GET /favicon.ico HTTP/1.1" 404 85
[09/Mar/2018 11:17:47] INFO [django.server:124] "GET / HTTP/1.1" 200 38830
[09/Mar/2018 11:17:48] INFO [django.server:124] "GET /api/column/postList/ HTTP/1.1" 200 11658
[09/Mar/2018 11:18:00] INFO [django.server:124] "POST /api/member/login/ HTTP/1.1" 200 334
[09/Mar/2018 11:18:00] INFO [django.server:124] "GET / HTTP/1.1" 200 38700
[09/Mar/2018 11:18:01] INFO [django.server:124] "GET /api/column/postList/ HTTP/1.1" 200 11658
[09/Mar/2018 11:18:01] INFO [django.server:124] "POST /api/member/userInfo/ HTTP/1.1" 200 142
[09/Mar/2018 11:18:07] INFO [django.server:124] "GET /write/ HTTP/1.1" 200 27515
[09/Mar/2018 11:18:09] INFO [django.server:124] "POST /api/column/isauthor/ HTTP/1.1" 200 15
[09/Mar/2018 11:18:09] INFO [django.server:124] "POST /api/member/userInfo/ HTTP/1.1" 200 142
[09/Mar/2018 11:18:22] INFO [django.server:124] "POST /api/column/tmpimageupload/ HTTP/1.1" 201 129
[09/Mar/2018 11:19:03] INFO [django.server:124] "GET / HTTP/1.1" 200 38830
[09/Mar/2018 11:19:05] INFO [django.server:124] "GET /api/column/postList/ HTTP/1.1" 200 11658
[09/Mar/2018 11:19:05] WARNING [django.request:152] Not Found: /favicon.ico
[09/Mar/2018 11:19:05] WARNING [django.server:124] "GET /favicon.ico HTTP/1.1" 404 85
[09/Mar/2018 11:19:19] INFO [django.server:124] "POST /api/member/login/ HTTP/1.1" 200 334
[09/Mar/2018 11:19:19] INFO [django.server:124] "GET / HTTP/1.1" 200 38700
[09/Mar/2018 11:19:20] INFO [django.server:124] "GET /api/column/postList/ HTTP/1.1" 200 11658
[09/Mar/2018 11:19:20] INFO [django.server:124] "POST /api/member/userInfo/ HTTP/1.1" 200 142
[09/Mar/2018 11:19:24] INFO [django.server:124] "GET /write/ HTTP/1.1" 200 27515
[09/Mar/2018 11:19:26] INFO [django.server:124] "POST /api/column/isauthor/ HTTP/1.1" 200 15
[09/Mar/2018 11:19:26] INFO [django.server:124] "POST /api/member/userInfo/ HTTP/1.1" 200 142
[09/Mar/2018 11:19:37] WARNING [django.server:124] "POST /api/column/tmpimageupload/ HTTP/1.1" 401 49
[09/Mar/2018 11:21:06] INFO [django.server:124] "OPTIONS /api/column/tmpimageupload/ HTTP/1.1" 200 0
[09/Mar/2018 11:21:06] WARNING [django.server:124] "POST /api/column/tmpimageupload/ HTTP/1.1" 401 49
[09/Mar/2018 11:21:35] WARNING [django.server:124] "POST /api/column/tmpimageupload/ HTTP/1.1" 401 49
[09/Mar/2018 11:22:16] INFO [django.server:124] "GET / HTTP/1.1" 200 38830
[09/Mar/2018 11:22:17] INFO [django.server:124] "GET /api/column/postList/ HTTP/1.1" 200 11658
[09/Mar/2018 11:22:19] INFO [django.server:124] "GET /write/ HTTP/1.1" 200 38830
[09/Mar/2018 11:22:22] INFO [django.server:124] "GET /api/column/postList/ HTTP/1.1" 200 11658
[09/Mar/2018 11:23:23] ERROR [django.request:135] Internal Server Error: /api/column/tmpimageupload/
Traceback (most recent call last):
  File "/Users/joohyonlee/.pyenv/versions/3.6.3/envs/docker-test/lib/python3.6/site-packages/django/core/handlers/exception.py", line 41, in inner
    response = get_response(request)
  File "/Users/joohyonlee/.pyenv/versions/3.6.3/envs/docker-test/lib/python3.6/site-packages/django/core/handlers/base.py", line 187, in _get_response
    response = self.process_exception_by_middleware(e, request)
  File "/Users/joohyonlee/.pyenv/versions/3.6.3/envs/docker-test/lib/python3.6/site-packages/django/core/handlers/base.py", line 185, in _get_response
    response = wrapped_callback(request, *callback_args, **callback_kwargs)
  File "/Users/joohyonlee/.pyenv/versions/3.6.3/envs/docker-test/lib/python3.6/site-packages/django/views/decorators/csrf.py", line 58, in wrapped_view
    return view_func(*args, **kwargs)
  File "/Users/joohyonlee/.pyenv/versions/3.6.3/envs/docker-test/lib/python3.6/site-packages/django/views/generic/base.py", line 68, in view
    return self.dispatch(request, *args, **kwargs)
  File "/Users/joohyonlee/.pyenv/versions/3.6.3/envs/docker-test/lib/python3.6/site-packages/rest_framework/views.py", line 494, in dispatch
    response = self.handle_exception(exc)
  File "/Users/joohyonlee/.pyenv/versions/3.6.3/envs/docker-test/lib/python3.6/site-packages/rest_framework/views.py", line 454, in handle_exception
    self.raise_uncaught_exception(exc)
  File "/Users/joohyonlee/.pyenv/versions/3.6.3/envs/docker-test/lib/python3.6/site-packages/rest_framework/views.py", line 491, in dispatch
    response = handler(request, *args, **kwargs)
  File "/Users/joohyonlee/devocto/octocolumn/octocolumn/column/apis/tmp.py", line 136, in post
    user = User.objects.filter(pk=self.request.user.id).get()
  File "/Users/joohyonlee/.pyenv/versions/3.6.3/envs/docker-test/lib/python3.6/site-packages/django/db/models/query.py", line 380, in get
    self.model._meta.object_name
member.models.user.DoesNotExist: User matching query does not exist.
[09/Mar/2018 11:23:23] ERROR [django.server:124] "POST /api/column/tmpimageupload/ HTTP/1.1" 500 27
[09/Mar/2018 11:24:08] INFO [django.server:124] "GET / HTTP/1.1" 200 38830
[09/Mar/2018 11:24:09] INFO [django.server:124] "GET /api/column/postList/ HTTP/1.1" 200 11658
[09/Mar/2018 11:24:27] INFO [django.server:124] "POST /api/member/login/ HTTP/1.1" 200 334
[09/Mar/2018 11:24:27] INFO [django.server:124] "GET / HTTP/1.1" 200 38700
[09/Mar/2018 11:24:28] INFO [django.server:124] "GET /api/column/postList/ HTTP/1.1" 200 11658
[09/Mar/2018 11:24:28] INFO [django.server:124] "POST /api/member/userInfo/ HTTP/1.1" 200 142
[09/Mar/2018 11:24:35] INFO [django.server:124] "GET /write/ HTTP/1.1" 200 27515
[09/Mar/2018 11:24:35] INFO [django.server:124] "POST /api/column/isauthor/ HTTP/1.1" 200 15
[09/Mar/2018 11:24:35] INFO [django.server:124] "POST /api/member/userInfo/ HTTP/1.1" 200 142
[09/Mar/2018 11:24:46] INFO [django.server:124] "POST /api/column/tmpimageupload/ HTTP/1.1" 201 129
[09/Mar/2018 11:29:07] ERROR [django.request:135] Internal Server Error: /api/column/tmpimageupload/
Traceback (most recent call last):
  File "/Users/joohyonlee/.pyenv/versions/3.6.3/envs/docker-test/lib/python3.6/site-packages/django/core/handlers/exception.py", line 41, in inner
    response = get_response(request)
  File "/Users/joohyonlee/.pyenv/versions/3.6.3/envs/docker-test/lib/python3.6/site-packages/django/core/handlers/base.py", line 187, in _get_response
    response = self.process_exception_by_middleware(e, request)
  File "/Users/joohyonlee/.pyenv/versions/3.6.3/envs/docker-test/lib/python3.6/site-packages/django/core/handlers/base.py", line 185, in _get_response
    response = wrapped_callback(request, *callback_args, **callback_kwargs)
  File "/Users/joohyonlee/.pyenv/versions/3.6.3/envs/docker-test/lib/python3.6/site-packages/django/views/decorators/csrf.py", line 58, in wrapped_view
    return view_func(*args, **kwargs)
  File "/Users/joohyonlee/.pyenv/versions/3.6.3/envs/docker-test/lib/python3.6/site-packages/django/views/generic/base.py", line 68, in view
    return self.dispatch(request, *args, **kwargs)
  File "/Users/joohyonlee/.pyenv/versions/3.6.3/envs/docker-test/lib/python3.6/site-packages/rest_framework/views.py", line 494, in dispatch
    response = self.handle_exception(exc)
  File "/Users/joohyonlee/.pyenv/versions/3.6.3/envs/docker-test/lib/python3.6/site-packages/rest_framework/views.py", line 454, in handle_exception
    self.raise_uncaught_exception(exc)
  File "/Users/joohyonlee/.pyenv/versions/3.6.3/envs/docker-test/lib/python3.6/site-packages/rest_framework/views.py", line 491, in dispatch
    response = handler(request, *args, **kwargs)
  File "/Users/joohyonlee/devocto/octocolumn/octocolumn/column/apis/tmp.py", line 136, in post
    user = User.objects.filter(pk=self.request.user.id).get()
  File "/Users/joohyonlee/.pyenv/versions/3.6.3/envs/docker-test/lib/python3.6/site-packages/django/db/models/query.py", line 380, in get
    self.model._meta.object_name
member.models.user.DoesNotExist: User matching query does not exist.
[09/Mar/2018 11:29:07] ERROR [django.server:124] "POST /api/column/tmpimageupload/ HTTP/1.1" 500 27
[09/Mar/2018 11:30:04] WARNING [django.server:124] "POST /api/member/signup/ HTTP/1.1" 400 66
[09/Mar/2018 11:30:30] INFO [django.server:124] "POST /api/member/signup/ HTTP/1.1" 201 47
[09/Mar/2018 11:32:01] INFO [django.server:124] "OPTIONS /api/column/tmpimageupload/ HTTP/1.1" 200 0
[09/Mar/2018 11:32:01] ERROR [django.request:135] Internal Server Error: /api/column/tmpimageupload/
Traceback (most recent call last):
  File "/Users/joohyonlee/.pyenv/versions/3.6.3/envs/docker-test/lib/python3.6/site-packages/django/core/handlers/exception.py", line 41, in inner
    response = get_response(request)
  File "/Users/joohyonlee/.pyenv/versions/3.6.3/envs/docker-test/lib/python3.6/site-packages/django/core/handlers/base.py", line 187, in _get_response
    response = self.process_exception_by_middleware(e, request)
  File "/Users/joohyonlee/.pyenv/versions/3.6.3/envs/docker-test/lib/python3.6/site-packages/django/core/handlers/base.py", line 185, in _get_response
    response = wrapped_callback(request, *callback_args, **callback_kwargs)
  File "/Users/joohyonlee/.pyenv/versions/3.6.3/envs/docker-test/lib/python3.6/site-packages/django/views/decorators/csrf.py", line 58, in wrapped_view
    return view_func(*args, **kwargs)
  File "/Users/joohyonlee/.pyenv/versions/3.6.3/envs/docker-test/lib/python3.6/site-packages/django/views/generic/base.py", line 68, in view
    return self.dispatch(request, *args, **kwargs)
  File "/Users/joohyonlee/.pyenv/versions/3.6.3/envs/docker-test/lib/python3.6/site-packages/rest_framework/views.py", line 494, in dispatch
    response = self.handle_exception(exc)
  File "/Users/joohyonlee/.pyenv/versions/3.6.3/envs/docker-test/lib/python3.6/site-packages/rest_framework/views.py", line 454, in handle_exception
    self.raise_uncaught_exception(exc)
  File "/Users/joohyonlee/.pyenv/versions/3.6.3/envs/docker-test/lib/python3.6/site-packages/rest_framework/views.py", line 491, in dispatch
    response = handler(request, *args, **kwargs)
  File "/Users/joohyonlee/devocto/octocolumn/octocolumn/column/apis/tmp.py", line 136, in post
    user = User.objects.filter(pk=self.request.user.id).get()
  File "/Users/joohyonlee/.pyenv/versions/3.6.3/envs/docker-test/lib/python3.6/site-packages/django/db/models/query.py", line 380, in get
    self.model._meta.object_name
member.models.user.DoesNotExist: User matching query does not exist.
[09/Mar/2018 11:32:01] ERROR [django.server:124] "POST /api/column/tmpimageupload/ HTTP/1.1" 500 27
[09/Mar/2018 11:38:08] INFO [django.server:124] "GET /write/ HTTP/1.1" 200 27515
[09/Mar/2018 11:38:08] INFO [django.server:124] "POST /api/column/isauthor/ HTTP/1.1" 200 15
[09/Mar/2018 11:38:08] INFO [django.server:124] "POST /api/member/userInfo/ HTTP/1.1" 200 142
[09/Mar/2018 11:38:17] INFO [django.server:124] "POST /api/column/tmpimageupload/ HTTP/1.1" 201 129
[09/Mar/2018 11:38:36] INFO [django.server:124] "GET /write/ HTTP/1.1" 200 27515
[09/Mar/2018 11:38:36] INFO [django.server:124] "POST /api/column/isauthor/ HTTP/1.1" 200 15
[09/Mar/2018 11:38:36] INFO [django.server:124] "POST /api/member/userInfo/ HTTP/1.1" 200 142
[09/Mar/2018 11:38:42] INFO [django.server:124] "POST /api/column/tmpimageupload/ HTTP/1.1" 201 127
[09/Mar/2018 11:39:29] ERROR [django.request:135] Internal Server Error: /api/column/tmpimageupload/
Traceback (most recent call last):
  File "/Users/joohyonlee/.pyenv/versions/3.6.3/envs/docker-test/lib/python3.6/site-packages/django/core/handlers/exception.py", line 41, in inner
    response = get_response(request)
  File "/Users/joohyonlee/.pyenv/versions/3.6.3/envs/docker-test/lib/python3.6/site-packages/django/core/handlers/base.py", line 187, in _get_response
    response = self.process_exception_by_middleware(e, request)
  File "/Users/joohyonlee/.pyenv/versions/3.6.3/envs/docker-test/lib/python3.6/site-packages/django/core/handlers/base.py", line 185, in _get_response
    response = wrapped_callback(request, *callback_args, **callback_kwargs)
  File "/Users/joohyonlee/.pyenv/versions/3.6.3/envs/docker-test/lib/python3.6/site-packages/django/views/decorators/csrf.py", line 58, in wrapped_view
    return view_func(*args, **kwargs)
  File "/Users/joohyonlee/.pyenv/versions/3.6.3/envs/docker-test/lib/python3.6/site-packages/django/views/generic/base.py", line 68, in view
    return self.dispatch(request, *args, **kwargs)
  File "/Users/joohyonlee/.pyenv/versions/3.6.3/envs/docker-test/lib/python3.6/site-packages/rest_framework/views.py", line 494, in dispatch
    response = self.handle_exception(exc)
  File "/Users/joohyonlee/.pyenv/versions/3.6.3/envs/docker-test/lib/python3.6/site-packages/rest_framework/views.py", line 454, in handle_exception
    self.raise_uncaught_exception(exc)
  File "/Users/joohyonlee/.pyenv/versions/3.6.3/envs/docker-test/lib/python3.6/site-packages/rest_framework/views.py", line 491, in dispatch
    response = handler(request, *args, **kwargs)
  File "/Users/joohyonlee/devocto/octocolumn/octocolumn/column/apis/tmp.py", line 136, in post
    user = User.objects.filter(pk=self.request.user.id).get()
  File "/Users/joohyonlee/.pyenv/versions/3.6.3/envs/docker-test/lib/python3.6/site-packages/django/db/models/query.py", line 380, in get
    self.model._meta.object_name
member.models.user.DoesNotExist: User matching query does not exist.
[09/Mar/2018 11:39:29] ERROR [django.server:124] "POST /api/column/tmpimageupload/ HTTP/1.1" 500 27
[09/Mar/2018 11:50:26] INFO [django.server:124] "GET /write/ HTTP/1.1" 200 27515
[09/Mar/2018 11:50:27] INFO [django.server:124] "POST /api/column/isauthor/ HTTP/1.1" 200 15
[09/Mar/2018 11:50:27] INFO [django.server:124] "POST /api/member/userInfo/ HTTP/1.1" 200 142
[09/Mar/2018 11:50:35] INFO [django.server:124] "POST /api/column/tmpimageupload/ HTTP/1.1" 201 129
[09/Mar/2018 11:51:37] INFO [django.server:124] "GET /write/ HTTP/1.1" 200 27515
[09/Mar/2018 11:51:38] INFO [django.server:124] "POST /api/column/isauthor/ HTTP/1.1" 200 15
[09/Mar/2018 11:51:38] INFO [django.server:124] "POST /api/member/userInfo/ HTTP/1.1" 200 142
[14/Mar/2018 15:19:43] INFO [django.server:124] "GET / HTTP/1.1" 200 38704
[14/Mar/2018 15:19:45] INFO [django.server:124] "GET /api/column/postList/ HTTP/1.1" 200 2
[14/Mar/2018 15:19:45] WARNING [django.request:152] Not Found: /favicon.ico
[14/Mar/2018 15:19:45] WARNING [django.server:124] "GET /favicon.ico HTTP/1.1" 404 85
[14/Mar/2018 15:27:48] INFO [django.server:124] "GET / HTTP/1.1" 200 38649
[14/Mar/2018 15:27:50] INFO [django.server:124] "GET /api/column/postList/ HTTP/1.1" 200 2
[14/Mar/2018 15:27:51] INFO [django.server:124] "GET / HTTP/1.1" 200 38649
[14/Mar/2018 15:27:52] INFO [django.server:124] "GET /api/column/postList/ HTTP/1.1" 200 2
[14/Mar/2018 15:36:34] INFO [django.server:124] "GET / HTTP/1.1" 200 38649
[14/Mar/2018 15:36:36] INFO [django.server:124] "GET /api/column/postList/ HTTP/1.1" 200 2
[14/Mar/2018 15:36:38] INFO [django.server:124] "GET / HTTP/1.1" 200 38649
[14/Mar/2018 15:36:39] INFO [django.server:124] "GET /api/column/postList/ HTTP/1.1" 200 2
[14/Mar/2018 15:38:52] INFO [django.server:124] "GET / HTTP/1.1" 200 38649
[14/Mar/2018 15:38:53] INFO [django.server:124] "GET /api/column/postList/ HTTP/1.1" 200 2
